Workbook

Sheet Instructions
A1: Instructions:
A3: 1. Pick one of the orange tabs that has not been filled in already
A4: 2. Follow the instructions on that orange tab
A5: 3. Once all team members have filled their respective orange tabs, check the 'Team Availablity' tab
A6: and change the time zone value in that 'Team Availability' tab to your time zone to see team availability in your time zone

Sheet Jaycie Liu
A1: Step 1: Rename the sheet name with your name, for example 'Member 1 Name' to 'Your Name' | J1: Time Zone
A2: Step 2: Choose your time zone from yellow drop down box | J2: PST
A3: Step 3: Enter '1' in all 30-minute slots you're NOT available in orange area | J3: {=_xlfn.SWITCH(J2,"PST",0,"MST",1,"CST",2,"EST",3,0)} -> 0
A6: Time | B6: Monday | C6: Tuesday | D6: Wednesday | E6: Thursday | F6: Friday | G6: Saturday | H6: Sunday
A7: =TEXT(TIME(3,0,0)+$J$3/24,"h:mm AM/PM") & " - " & TEXT(TIME(3,30,0)+$J$3/24,"h:mm AM/PM") -> 3:00 AM - 3:30 AM | B7: 1 | C7: 1 | D7: 1 | E7: 1 | F7: 1 | G7: 1 | H7: 1
A8: =TEXT(TIMEVALUE(LEFT(A7,FIND(" -",A7)-1))+TIME(0,30,0), "h:mm AM/PM") & " - " & TEXT(TIMEVALUE(MID(A7,FIND("- ",A7)+2,99))+TIME(0,30,0), "h:mm AM/PM") -> 3:30 AM - 4:00 AM | B8: 1 | C8: 1 | D8: 1 | E8: 1 | F8: 1 | G8: 1 | H8: 1
A9: =TEXT(TIMEVALUE(LEFT(A8,FIND(" -",A8)-1))+TIME(0,30,0), "h:mm AM/PM") & " - " & TEXT(TIMEVALUE(MID(A8,FIND("- ",A8)+2,99))+TIME(0,30,0), "h:mm AM/PM") -> 4:00 AM - 4:30 AM | B9: 1 | C9: 1 | D9: 1 | E9: 1 | F9: 1 | G9: 1 | H9: 1
A10: =TEXT(TIMEVALUE(LEFT(A9,FIND(" -",A9)-1))+TIME(0,30,0), "h:mm AM/PM") & " - " & TEXT(TIMEVALUE(MID(A9,FIND("- ",A9)+2,99))+TIME(0,30,0), "h:mm AM/PM") -> 4:30 AM - 5:00 AM | B10: 1 | C10: 1 | D10: 1 | E10: 1 | F10: 1 | G10: 1 | H10: 1
A11: =TEXT(TIMEVALUE(LEFT(A10,FIND(" -",A10)-1))+TIME(0,30,0), "h:mm AM/PM") & " - " & TEXT(TIMEVALUE(MID(A10,FIND("- ",A10)+2,99))+TIME(0,30,0), "h:mm AM/PM") -> 5:00 AM - 5:30 AM | B11: 1 | C11: 1 | D11: 1 | E11: 1 | F11: 1 | G11: 1 | H11: 1
A12: =TEXT(TIMEVALUE(LEFT(A11,FIND(" -",A11)-1))+TIME(0,30,0), "h:mm AM/PM") & " - " & TEXT(TIMEVALUE(MID(A11,FIND("- ",A11)+2,99))+TIME(0,30,0), "h:mm AM/PM") -> 5:30 AM - 6:00 AM | B12: 1 | C12: 1 | D12: 1 | E12: 1 | F12: 1 | G12: 1 | H12: 1
A13: =TEXT(TIMEVALUE(LEFT(A12,FIND(" -",A12)-1))+TIME(0,30,0), "h:mm AM/PM") & " - " & TEXT(TIMEVALUE(MID(A12,FIND("- ",A12)+2,99))+TIME(0,30,0), "h:mm AM/PM") -> 6:00 AM - 6:30 AM | B13: 1 | C13: 1 | D13: 1 | E13: 1 | F13: 1 | G13: 1 | H13: 1
A14: =TEXT(TIMEVALUE(LEFT(A13,FIND(" -",A13)-1))+TIME(0,30,0), "h:mm AM/PM") & " - " & TEXT(TIMEVALUE(MID(A13,FIND("- ",A13)+2,99))+TIME(0,30,0), "h:mm AM/PM") -> 6:30 AM - 7:00 AM | B14: 1 | C14: 1 | D14: 1 | E14: 1 | F14: 1 | G14: 1 | H14: 1
A15: =TEXT(TIMEVALUE(LEFT(A14,FIND(" -",A14)-1))+TIME(0,30,0), "h:mm AM/PM") & " - " & TEXT(TIMEVALUE(MID(A14,FIND("- ",A14)+2,99))+TIME(0,30,0), "h:mm AM/PM") -> 7:00 AM - 7:30 AM | B15: 1 | C15: 1 | D15: 1 | E15: 1 | F15: 1 | G15: 1 | H15: 1
A16: =TEXT(TIMEVALUE(LEFT(A15,FIND(" -",A15)-1))+TIME(0,30,0), "h:mm AM/PM") & " - " & TEXT(TIMEVALUE(MID(A15,FIND("- ",A15)+2,99))+TIME(0,30,0), "h:mm AM/PM") -> 7:30 AM - 8:00 AM | B16: 1 | C16: 1 | D16: 1 | E16: 1 | F16: 1 | G16: 1 | H16: 1
A17: =TEXT(TIMEVALUE(LEFT(A16,FIND(" -",A16)-1))+TIME(0,30,0), "h:mm AM/PM") & " - " & TEXT(TIMEVALUE(MID(A16,FIND("- ",A16)+2,99))+TIME(0,30,0), "h:mm AM/PM") -> 8:00 AM - 8:30 AM | B17: 1 | C17: 1 | D17: 1 | E17: 1 | F17: 1 | G17: 1 | H17: 1
A18: =TEXT(TIMEVALUE(LEFT(A17,FIND(" -",A17)-1))+TIME(0,30,0), "h:mm AM/PM") & " - " & TEXT(TIMEVALUE(MID(A17,FIND("- ",A17)+2,99))+TIME(0,30,0), "h:mm AM/PM") -> 8:30 AM - 9:00 AM
A19: =TEXT(TIMEVALUE(LEFT(A18,FIND(" -",A18)-1))+TIME(0,30,0), "h:mm AM/PM") & " - " & TEXT(TIMEVALUE(MID(A18,FIND("- ",A18)+2,99))+TIME(0,30,0), "h:mm AM/PM") -> 9:00 AM - 9:30 AM
A20: =TEXT(TIMEVALUE(LEFT(A19,FIND(" -",A19)-1))+TIME(0,30,0), "h:mm AM/PM") & " - " & TEXT(TIMEVALUE(MID(A19,FIND("- ",A19)+2,99))+TIME(0,30,0), "h:mm AM/PM") -> 9:30 AM - 10:00 AM
A21: =TEXT(TIMEVALUE(LEFT(A20,FIND(" -",A20)-1))+TIME(0,30,0), "h:mm AM/PM") & " - " & TEXT(TIMEVALUE(MID(A20,FIND("- ",A20)+2,99))+TIME(0,30,0), "h:mm AM/PM") -> 10:00 AM - 10:30 AM
A22: =TEXT(TIMEVALUE(LEFT(A21,FIND(" -",A21)-1))+TIME(0,30,0), "h:mm AM/PM") & " - " & TEXT(TIMEVALUE(MID(A21,FIND("- ",A21)+2,99))+TIME(0,30,0), "h:mm AM/PM") -> 10:30 AM - 11:00 AM | B22: 1 | C22: 1 | D22: 1 | E22: 1
A23: =TEXT(TIMEVALUE(LEFT(A22,FIND(" -",A22)-1))+TIME(0,30,0), "h:mm AM/PM") & " - " & TEXT(TIMEVALUE(MID(A22,FIND("- ",A22)+2,99))+TIME(0,30,0), "h:mm AM/PM") -> 11:00 AM - 11:30 AM | B23: 1 | C23: 1 | D23: 1 | E23: 1
A24: =TEXT(TIMEVALUE(LEFT(A23,FIND(" -",A23)-1))+TIME(0,30,0), "h:mm AM/PM") & " - " & TEXT(TIMEVALUE(MID(A23,FIND("- ",A23)+2,99))+TIME(0,30,0), "h:mm AM/PM") -> 11:30 AM - 12:00 PM | B24: 1 | C24: 1 | D24: 1 | E24: 1
A25: =TEXT(TIMEVALUE(LEFT(A24,FIND(" -",A24)-1))+TIME(0,30,0), "h:mm AM/PM") & " - " & TEXT(TIMEVALUE(MID(A24,FIND("- ",A24)+2,99))+TIME(0,30,0), "h:mm AM/PM") -> 12:00 PM - 12:30 PM | B25: 1 | C25: 1 | D25: 1 | E25: 1
A26: =TEXT(TIMEVALUE(LEFT(A25,FIND(" -",A25)-1))+TIME(0,30,0), "h:mm AM/PM") & " - " & TEXT(TIMEVALUE(MID(A25,FIND("- ",A25)+2,99))+TIME(0,30,0), "h:mm AM/PM") -> 12:30 PM - 1:00 PM | B26: 1 | C26: 1 | D26: 1 | E26: 1
A27: =TEXT(TIMEVALUE(LEFT(A26,FIND(" -",A26)-1))+TIME(0,30,0), "h:mm AM/PM") & " - " & TEXT(TIMEVALUE(MID(A26,FIND("- ",A26)+2,99))+TIME(0,30,0), "h:mm AM/PM") -> 1:00 PM - 1:30 PM | B27: 1 | C27: 1 | D27: 1 | E27: 1
A28: =TEXT(TIMEVALUE(LEFT(A27,FIND(" -",A27)-1))+TIME(0,30,0), "h:mm AM/PM") & " - " & TEXT(TIMEVALUE(MID(A27,FIND("- ",A27)+2,99))+TIME(0,30,0), "h:mm AM/PM") -> 1:30 PM - 2:00 PM | C28: 1 | E28: 1
A29: =TEXT(TIMEVALUE(LEFT(A28,FIND(" -",A28)-1))+TIME(0,30,0), "h:mm AM/PM") & " - " & TEXT(TIMEVALUE(MID(A28,FIND("- ",A28)+2,99))+TIME(0,30,0), "h:mm AM/PM") -> 2:00 PM - 2:30 PM | C29: 1 | E29: 1
A30: =TEXT(TIMEVALUE(LEFT(A29,FIND(" -",A29)-1))+TIME(0,30,0), "h:mm AM/PM") & " - " & TEXT(TIMEVALUE(MID(A29,FIND("- ",A29)+2,99))+TIME(0,30,0), "h:mm AM/PM") -> 2:30 PM - 3:00 PM
A31: =TEXT(TIMEVALUE(LEFT(A30,FIND(" -",A30)-1))+TIME(0,30,0), "h:mm AM/PM") & " - " & TEXT(TIMEVALUE(MID(A30,FIND("- ",A30)+2,99))+TIME(0,30,0), "h:mm AM/PM") -> 3:00 PM - 3:30 PM
A32: =TEXT(TIMEVALUE(LEFT(A31,FIND(" -",A31)-1))+TIME(0,30,0), "h:mm AM/PM") & " - " & TEXT(TIMEVALUE(MID(A31,FIND("- ",A31)+2,99))+TIME(0,30,0), "h:mm AM/PM") -> 3:30 PM - 4:00 PM
A33: =TEXT(TIMEVALUE(LEFT(A32,FIND(" -",A32)-1))+TIME(0,30,0), "h:mm AM/PM") & " - " & TEXT(TIMEVALUE(MID(A32,FIND("- ",A32)+2,99))+TIME(0,30,0), "h:mm AM/PM") -> 4:00 PM - 4:30 PM
A34: =TEXT(TIMEVALUE(LEFT(A33,FIND(" -",A33)-1))+TIME(0,30,0), "h:mm AM/PM") & " - " & TEXT(TIMEVALUE(MID(A33,FIND("- ",A33)+2,99))+TIME(0,30,0), "h:mm AM/PM") -> 4:30 PM - 5:00 PM
A35: =TEXT(TIMEVALUE(LEFT(A34,FIND(" -",A34)-1))+TIME(0,30,0), "h:mm AM/PM") & " - " & TEXT(TIMEVALUE(MID(A34,FIND("- ",A34)+2,99))+TIME(0,30,0), "h:mm AM/PM") -> 5:00 PM - 5:30 PM
A36: =TEXT(TIMEVALUE(LEFT(A35,FIND(" -",A35)-1))+TIME(0,30,0), "h:mm AM/PM") & " - " & TEXT(TIMEVALUE(MID(A35,FIND("- ",A35)+2,99))+TIME(0,30,0), "h:mm AM/PM") -> 5:30 PM - 6:00 PM | D36: 1
A37: =TEXT(TIMEVALUE(LEFT(A36,FIND(" -",A36)-1))+TIME(0,30,0), "h:mm AM/PM") & " - " & TEXT(TIMEVALUE(MID(A36,FIND("- ",A36)+2,99))+TIME(0,30,0), "h:mm AM/PM") -> 6:00 PM - 6:30 PM | D37: 1
A38: =TEXT(TIMEVALUE(LEFT(A37,FIND(" -",A37)-1))+TIME(0,30,0), "h:mm AM/PM") & " - " & TEXT(TIMEVALUE(MID(A37,FIND("- ",A37)+2,99))+TIME(0,30,0), "h:mm AM/PM") -> 6:30 PM - 7:00 PM | D38: 1
A39: =TEXT(TIMEVALUE(LEFT(A38,FIND(" -",A38)-1))+TIME(0,30,0), "h:mm AM/PM") & " - " & TEXT(TIMEVALUE(MID(A38,FIND("- ",A38)+2,99))+TIME(0,30,0), "h:mm AM/PM") -> 7:00 PM - 7:30 PM | D39: 1
A40: =TEXT(TIMEVALUE(LEFT(A39,FIND(" -",A39)-1))+TIME(0,30,0), "h:mm AM/PM") & " - " & TEXT(TIMEVALUE(MID(A39,FIND("- ",A39)+2,99))+TIME(0,30,0), "h:mm AM/PM") -> 7:30 PM - 8:00 PM | D40: 1
A41: =TEXT(TIMEVALUE(LEFT(A40,FIND(" -",A40)-1))+TIME(0,30,0), "h:mm AM/PM") & " - " & TEXT(TIMEVALUE(MID(A40,FIND("- ",A40)+2,99))+TIME(0,30,0), "h:mm AM/PM") -> 8:00 PM - 8:30 PM | D41: 1
A42: =TEXT(TIMEVALUE(LEFT(A41,FIND(" -",A41)-1))+TIME(0,30,0), "h:mm AM/PM") & " - " & TEXT(TIMEVALUE(MID(A41,FIND("- ",A41)+2,99))+TIME(0,30,0), "h:mm AM/PM") -> 8:30 PM - 9:00 PM | D42: 1
...

Sheet Orson Lee
A1: Step 1: Rename the sheet name with your name, for example 'Member 2 Name' to 'Your Name' | J1: Time Zone
A2: Step 2: Choose your time zone from yellow drop down box | J2: PST
A3: Step 3: Enter '1' in all 30-minute slots you're NOT available in orange area | J3: {=_xlfn.SWITCH(J2,"PST",0,"MST",1,"CST",2,"EST",3,0)} -> 0
A6: Time | B6: Monday | C6: Tuesday | D6: Wednesday | E6: Thursday | F6: Friday | G6: Saturday | H6: Sunday
A7: =TEXT(TIME(3,0,0)+$J$3/24,"h:mm AM/PM") & " - " & TEXT(TIME(3,30,0)+$J$3/24,"h:mm AM/PM") -> 3:00 AM - 3:30 AM | B7: 1 | C7: 1 | D7: 1 | E7: 1 | F7: 1 | G7: 1 | H7: 1
A8: =TEXT(TIMEVALUE(LEFT(A7,FIND(" -",A7)-1))+TIME(0,30,0), "h:mm AM/PM") & " - " & TEXT(TIMEVALUE(MID(A7,FIND("- ",A7)+2,99))+TIME(0,30,0), "h:mm AM/PM") -> 3:30 AM - 4:00 AM | B8: 1 | C8: 1 | D8: 1 | E8: 1 | F8: 1 | G8: 1 | H8: 1
A9: =TEXT(TIMEVALUE(LEFT(A8,FIND(" -",A8)-1))+TIME(0,30,0), "h:mm AM/PM") & " - " & TEXT(TIMEVALUE(MID(A8,FIND("- ",A8)+2,99))+TIME(0,30,0), "h:mm AM/PM") -> 4:00 AM - 4:30 AM | B9: 1 | C9: 1 | D9: 1 | E9: 1 | F9: 1 | G9: 1 | H9: 1
A10: =TEXT(TIMEVALUE(LEFT(A9,FIND(" -",A9)-1))+TIME(0,30,0), "h:mm AM/PM") & " - " & TEXT(TIMEVALUE(MID(A9,FIND("- ",A9)+2,99))+TIME(0,30,0), "h:mm AM/PM") -> 4:30 AM - 5:00 AM | B10: 1 | C10: 1 | D10: 1 | E10: 1 | F10: 1 | G10: 1 | H10: 1
A11: =TEXT(TIMEVALUE(LEFT(A10,FIND(" -",A10)-1))+TIME(0,30,0), "h:mm AM/PM") & " - " & TEXT(TIMEVALUE(MID(A10,FIND("- ",A10)+2,99))+TIME(0,30,0), "h:mm AM/PM") -> 5:00 AM - 5:30 AM | B11: 1 | C11: 1 | D11: 1 | E11: 1 | F11: 1 | G11: 1 | H11: 1
A12: =TEXT(TIMEVALUE(LEFT(A11,FIND(" -",A11)-1))+TIME(0,30,0), "h:mm AM/PM") & " - " & TEXT(TIMEVALUE(MID(A11,FIND("- ",A11)+2,99))+TIME(0,30,0), "h:mm AM/PM") -> 5:30 AM - 6:00 AM | B12: 1 | C12: 1 | D12: 1 | E12: 1 | F12: 1 | G12: 1 | H12: 1
A13: =TEXT(TIMEVALUE(LEFT(A12,FIND(" -",A12)-1))+TIME(0,30,0), "h:mm AM/PM") & " - " & TEXT(TIMEVALUE(MID(A12,FIND("- ",A12)+2,99))+TIME(0,30,0), "h:mm AM/PM") -> 6:00 AM - 6:30 AM | B13: 1 | C13: 1 | D13: 1 | E13: 1 | F13: 1 | G13: 1 | H13: 1
A14: =TEXT(TIMEVALUE(LEFT(A13,FIND(" -",A13)-1))+TIME(0,30,0), "h:mm AM/PM") & " - " & TEXT(TIMEVALUE(MID(A13,FIND("- ",A13)+2,99))+TIME(0,30,0), "h:mm AM/PM") -> 6:30 AM - 7:00 AM | B14: 1 | C14: 1 | D14: 1 | E14: 1 | F14: 1 | G14: 1 | H14: 1
A15: =TEXT(TIMEVALUE(LEFT(A14,FIND(" -",A14)-1))+TIME(0,30,0), "h:mm AM/PM") & " - " & TEXT(TIMEVALUE(MID(A14,FIND("- ",A14)+2,99))+TIME(0,30,0), "h:mm AM/PM") -> 7:00 AM - 7:30 AM | B15: 1 | C15: 1 | D15: 1 | E15: 1 | F15: 1 | G15: 1 | H15: 1
A16: =TEXT(TIMEVALUE(LEFT(A15,FIND(" -",A15)-1))+TIME(0,30,0), "h:mm AM/PM") & " - " & TEXT(TIMEVALUE(MID(A15,FIND("- ",A15)+2,99))+TIME(0,30,0), "h:mm AM/PM") -> 7:30 AM - 8:00 AM | B16: 1 | C16: 1 | D16: 1 | E16: 1 | F16: 1 | G16: 1 | H16: 1
A17: =TEXT(TIMEVALUE(LEFT(A16,FIND(" -",A16)-1))+TIME(0,30,0), "h:mm AM/PM") & " - " & TEXT(TIMEVALUE(MID(A16,FIND("- ",A16)+2,99))+TIME(0,30,0), "h:mm AM/PM") -> 8:00 AM - 8:30 AM
A18: =TEXT(TIMEVALUE(LEFT(A17,FIND(" -",A17)-1))+TIME(0,30,0), "h:mm AM/PM") & " - " & TEXT(TIMEVALUE(MID(A17,FIND("- ",A17)+2,99))+TIME(0,30,0), "h:mm AM/PM") -> 8:30 AM - 9:00 AM
A19: =TEXT(TIMEVALUE(LEFT(A18,FIND(" -",A18)-1))+TIME(0,30,0), "h:mm AM/PM") & " - " & TEXT(TIMEVALUE(MID(A18,FIND("- ",A18)+2,99))+TIME(0,30,0), "h:mm AM/PM") -> 9:00 AM - 9:30 AM | C19: 1 | E19: 1
A20: =TEXT(TIMEVALUE(LEFT(A19,FIND(" -",A19)-1))+TIME(0,30,0), "h:mm AM/PM") & " - " & TEXT(TIMEVALUE(MID(A19,FIND("- ",A19)+2,99))+TIME(0,30,0), "h:mm AM/PM") -> 9:30 AM - 10:00 AM | C20: 1 | E20: 1
A21: =TEXT(TIMEVALUE(LEFT(A20,FIND(" -",A20)-1))+TIME(0,30,0), "h:mm AM/PM") & " - " & TEXT(TIMEVALUE(MID(A20,FIND("- ",A20)+2,99))+TIME(0,30,0), "h:mm AM/PM") -> 10:00 AM - 10:30 AM | C21: 1 | E21: 1
A22: =TEXT(TIMEVALUE(LEFT(A21,FIND(" -",A21)-1))+TIME(0,30,0), "h:mm AM/PM") & " - " & TEXT(TIMEVALUE(MID(A21,FIND("- ",A21)+2,99))+TIME(0,30,0), "h:mm AM/PM") -> 10:30 AM - 11:00 AM | C22: 1 | E22: 1 | F22: 1
A23: =TEXT(TIMEVALUE(LEFT(A22,FIND(" -",A22)-1))+TIME(0,30,0), "h:mm AM/PM") & " - " & TEXT(TIMEVALUE(MID(A22,FIND("- ",A22)+2,99))+TIME(0,30,0), "h:mm AM/PM") -> 11:00 AM - 11:30 AM | B23: 1 | C23: 1 | D23: 1 | E23: 1 | F23: 1 | G23: 1 | H23: 1
A24: =TEXT(TIMEVALUE(LEFT(A23,FIND(" -",A23)-1))+TIME(0,30,0), "h:mm AM/PM") & " - " & TEXT(TIMEVALUE(MID(A23,FIND("- ",A23)+2,99))+TIME(0,30,0), "h:mm AM/PM") -> 11:30 AM - 12:00 PM | B24: 1 | C24: 1 | D24: 1 | E24: 1 | F24: 1 | G24: 1 | H24: 1
A25: =TEXT(TIMEVALUE(LEFT(A24,FIND(" -",A24)-1))+TIME(0,30,0), "h:mm AM/PM") & " - " & TEXT(TIMEVALUE(MID(A24,FIND("- ",A24)+2,99))+TIME(0,30,0), "h:mm AM/PM") -> 12:00 PM - 12:30 PM | B25: 1 | C25: 1 | D25: 1 | E25: 1 | F25: 1 | G25: 1 | H25: 1
A26: =TEXT(TIMEVALUE(LEFT(A25,FIND(" -",A25)-1))+TIME(0,30,0), "h:mm AM/PM") & " - " & TEXT(TIMEVALUE(MID(A25,FIND("- ",A25)+2,99))+TIME(0,30,0), "h:mm AM/PM") -> 12:30 PM - 1:00 PM | B26: 1 | D26: 1 | F26: 1
A27: =TEXT(TIMEVALUE(LEFT(A26,FIND(" -",A26)-1))+TIME(0,30,0), "h:mm AM/PM") & " - " & TEXT(TIMEVALUE(MID(A26,FIND("- ",A26)+2,99))+TIME(0,30,0), "h:mm AM/PM") -> 1:00 PM - 1:30 PM | F27: 1
A28: =TEXT(TIMEVALUE(LEFT(A27,FIND(" -",A27)-1))+TIME(0,30,0), "h:mm AM/PM") & " - " & TEXT(TIMEVALUE(MID(A27,FIND("- ",A27)+2,99))+TIME(0,30,0), "h:mm AM/PM") -> 1:30 PM - 2:00 PM | B28: 1 | D28: 1 | F28: 1
A29: =TEXT(TIMEVALUE(LEFT(A28,FIND(" -",A28)-1))+TIME(0,30,0), "h:mm AM/PM") & " - " & TEXT(TIMEVALUE(MID(A28,FIND("- ",A28)+2,99))+TIME(0,30,0), "h:mm AM/PM") -> 2:00 PM - 2:30 PM | B29: 1 | D29: 1 | F29: 1
A30: =TEXT(TIMEVALUE(LEFT(A29,FIND(" -",A29)-1))+TIME(0,30,0), "h:mm AM/PM") & " - " & TEXT(TIMEVALUE(MID(A29,FIND("- ",A29)+2,99))+TIME(0,30,0), "h:mm AM/PM") -> 2:30 PM - 3:00 PM | B30: 1 | D30: 1 | F30: 1
A31: =TEXT(TIMEVALUE(LEFT(A30,FIND(" -",A30)-1))+TIME(0,30,0), "h:mm AM/PM") & " - " & TEXT(TIMEVALUE(MID(A30,FIND("- ",A30)+2,99))+TIME(0,30,0), "h:mm AM/PM") -> 3:00 PM - 3:30 PM | B31: 1 | D31: 1 | F31: 1
A32: =TEXT(TIMEVALUE(LEFT(A31,FIND(" -",A31)-1))+TIME(0,30,0), "h:mm AM/PM") & " - " & TEXT(TIMEVALUE(MID(A31,FIND("- ",A31)+2,99))+TIME(0,30,0), "h:mm AM/PM") -> 3:30 PM - 4:00 PM
A33: =TEXT(TIMEVALUE(LEFT(A32,FIND(" -",A32)-1))+TIME(0,30,0), "h:mm AM/PM") & " - " & TEXT(TIMEVALUE(MID(A32,FIND("- ",A32)+2,99))+TIME(0,30,0), "h:mm AM/PM") -> 4:00 PM - 4:30 PM | B33: 1 | C33: 1
A34: =TEXT(TIMEVALUE(LEFT(A33,FIND(" -",A33)-1))+TIME(0,30,0), "h:mm AM/PM") & " - " & TEXT(TIMEVALUE(MID(A33,FIND("- ",A33)+2,99))+TIME(0,30,0), "h:mm AM/PM") -> 4:30 PM - 5:00 PM | B34: 1 | C34: 1
A35: =TEXT(TIMEVALUE(LEFT(A34,FIND(" -",A34)-1))+TIME(0,30,0), "h:mm AM/PM") & " - " & TEXT(TIMEVALUE(MID(A34,FIND("- ",A34)+2,99))+TIME(0,30,0), "h:mm AM/PM") -> 5:00 PM - 5:30 PM | B35: 1 | C35: 1 | D35: 1 | F35: 1 | G35: 1 | H35: 1
A36: =TEXT(TIMEVALUE(LEFT(A35,FIND(" -",A35)-1))+TIME(0,30,0), "h:mm AM/PM") & " - " & TEXT(TIMEVALUE(MID(A35,FIND("- ",A35)+2,99))+TIME(0,30,0), "h:mm AM/PM") -> 5:30 PM - 6:00 PM | B36: 1 | C36: 1 | D36: 1 | F36: 1 | G36: 1 | H36: 1
A37: =TEXT(TIMEVALUE(LEFT(A36,FIND(" -",A36)-1))+TIME(0,30,0), "h:mm AM/PM") & " - " & TEXT(TIMEVALUE(MID(A36,FIND("- ",A36)+2,99))+TIME(0,30,0), "h:mm AM/PM") -> 6:00 PM - 6:30 PM | C37: 1 | G37: 1 | H37: 1
A38: =TEXT(TIMEVALUE(LEFT(A37,FIND(" -",A37)-1))+TIME(0,30,0), "h:mm AM/PM") & " - " & TEXT(TIMEVALUE(MID(A37,FIND("- ",A37)+2,99))+TIME(0,30,0), "h:mm AM/PM") -> 6:30 PM - 7:00 PM | C38: 1
A39: =TEXT(TIMEVALUE(LEFT(A38,FIND(" -",A38)-1))+TIME(0,30,0), "h:mm AM/PM") & " - " & TEXT(TIMEVALUE(MID(A38,FIND("- ",A38)+2,99))+TIME(0,30,0), "h:mm AM/PM") -> 7:00 PM - 7:30 PM | C39: 1
A40: =TEXT(TIMEVALUE(LEFT(A39,FIND(" -",A39)-1))+TIME(0,30,0), "h:mm AM/PM") & " - " & TEXT(TIMEVALUE(MID(A39,FIND("- ",A39)+2,99))+TIME(0,30,0), "h:mm AM/PM") -> 7:30 PM - 8:00 PM | C40: 1
A41: =TEXT(TIMEVALUE(LEFT(A40,FIND(" -",A40)-1))+TIME(0,30,0), "h:mm AM/PM") & " - " & TEXT(TIMEVALUE(MID(A40,FIND("- ",A40)+2,99))+TIME(0,30,0), "h:mm AM/PM") -> 8:00 PM - 8:30 PM | E41: 1
A42: =TEXT(TIMEVALUE(LEFT(A41,FIND(" -",A41)-1))+TIME(0,30,0), "h:mm AM/PM") & " - " & TEXT(TIMEVALUE(MID(A41,FIND("- ",A41)+2,99))+TIME(0,30,0), "h:mm AM/PM") -> 8:30 PM - 9:00 PM | E42: 1
...

Sheet Maria Herrmann
A1: Step 1: Rename the sheet name with your name, for example 'Member 3 Name' to 'Your Name' | J1: Time Zone
A2: Step 2: Choose your time zone from yellow drop down box | J2: EST
A3: Step 3: Enter '1' in all 30-minute slots you're NOT available in orange area | J3: {=_xlfn.SWITCH(J2,"PST",0,"MST",1,"CST",2,"EST",3,0)} -> 3
A6: Time | B6: Monday | C6: Tuesday | D6: Wednesday | E6: Thursday | F6: Friday | G6: Saturday | H6: Sunday
A7: =TEXT(TIME(3,0,0)+$J$3/24,"h:mm AM/PM") & " - " & TEXT(TIME(3,30,0)+$J$3/24,"h:mm AM/PM") -> 6:00 AM - 6:30 AM | B7: 1 | C7: 1 | D7: 1 | E7: 1 | F7: 1 | G7: 1 | H7: 1
A8: =TEXT(TIMEVALUE(LEFT(A7,FIND(" -",A7)-1))+TIME(0,30,0), "h:mm AM/PM") & " - " & TEXT(TIMEVALUE(MID(A7,FIND("- ",A7)+2,99))+TIME(0,30,0), "h:mm AM/PM") -> 6:30 AM - 7:00 AM | B8: 1 | C8: 1 | D8: 1 | E8: 1 | F8: 1 | G8: 1 | H8: 1
A9: =TEXT(TIMEVALUE(LEFT(A8,FIND(" -",A8)-1))+TIME(0,30,0), "h:mm AM/PM") & " - " & TEXT(TIMEVALUE(MID(A8,FIND("- ",A8)+2,99))+TIME(0,30,0), "h:mm AM/PM") -> 7:00 AM - 7:30 AM | B9: 1 | C9: 1 | D9: 1 | E9: 1 | F9: 1 | G9: 1 | H9: 1
A10: =TEXT(TIMEVALUE(LEFT(A9,FIND(" -",A9)-1))+TIME(0,30,0), "h:mm AM/PM") & " - " & TEXT(TIMEVALUE(MID(A9,FIND("- ",A9)+2,99))+TIME(0,30,0), "h:mm AM/PM") -> 7:30 AM - 8:00 AM | B10: 1 | C10: 1 | D10: 1 | E10: 1 | F10: 1 | G10: 1 | H10: 1
A11: =TEXT(TIMEVALUE(LEFT(A10,FIND(" -",A10)-1))+TIME(0,30,0), "h:mm AM/PM") & " - " & TEXT(TIMEVALUE(MID(A10,FIND("- ",A10)+2,99))+TIME(0,30,0), "h:mm AM/PM") -> 8:00 AM - 8:30 AM | B11: 1 | C11: 1 | D11: 1 | E11: 1 | F11: 1 | G11: 1 | H11: 1
A12: =TEXT(TIMEVALUE(LEFT(A11,FIND(" -",A11)-1))+TIME(0,30,0), "h:mm AM/PM") & " - " & TEXT(TIMEVALUE(MID(A11,FIND("- ",A11)+2,99))+TIME(0,30,0), "h:mm AM/PM") -> 8:30 AM - 9:00 AM | B12: 1 | C12: 1 | D12: 1 | E12: 1 | F12: 1 | G12: 1 | H12: 1
A13: =TEXT(TIMEVALUE(LEFT(A12,FIND(" -",A12)-1))+TIME(0,30,0), "h:mm AM/PM") & " - " & TEXT(TIMEVALUE(MID(A12,FIND("- ",A12)+2,99))+TIME(0,30,0), "h:mm AM/PM") -> 9:00 AM - 9:30 AM | B13: 1 | C13: 1 | D13: 1 | E13: 1 | F13: 1 | G13: 1 | H13: 1
A14: =TEXT(TIMEVALUE(LEFT(A13,FIND(" -",A13)-1))+TIME(0,30,0), "h:mm AM/PM") & " - " & TEXT(TIMEVALUE(MID(A13,FIND("- ",A13)+2,99))+TIME(0,30,0), "h:mm AM/PM") -> 9:30 AM - 10:00 AM | B14: 1 | F14: 1 | G14: 1 | H14: 1
A15: =TEXT(TIMEVALUE(LEFT(A14,FIND(" -",A14)-1))+TIME(0,30,0), "h:mm AM/PM") & " - " & TEXT(TIMEVALUE(MID(A14,FIND("- ",A14)+2,99))+TIME(0,30,0), "h:mm AM/PM") -> 10:00 AM - 10:30 AM | B15: 1 | F15: 1 | G15: 1 | H15: 1
A16: =TEXT(TIMEVALUE(LEFT(A15,FIND(" -",A15)-1))+TIME(0,30,0), "h:mm AM/PM") & " - " & TEXT(TIMEVALUE(MID(A15,FIND("- ",A15)+2,99))+TIME(0,30,0), "h:mm AM/PM") -> 10:30 AM - 11:00 AM | B16: 1 | C16: 1 | E16: 1 | F16: 1 | G16: 1 | H16: 1
A17: =TEXT(TIMEVALUE(LEFT(A16,FIND(" -",A16)-1))+TIME(0,30,0), "h:mm AM/PM") & " - " & TEXT(TIMEVALUE(MID(A16,FIND("- ",A16)+2,99))+TIME(0,30,0), "h:mm AM/PM") -> 11:00 AM - 11:30 AM | B17: 1 | C17: 1 | E17: 1
A18: =TEXT(TIMEVALUE(LEFT(A17,FIND(" -",A17)-1))+TIME(0,30,0), "h:mm AM/PM") & " - " & TEXT(TIMEVALUE(MID(A17,FIND("- ",A17)+2,99))+TIME(0,30,0), "h:mm AM/PM") -> 11:30 AM - 12:00 PM | B18: 1 | C18: 1 | E18: 1
A19: =TEXT(TIMEVALUE(LEFT(A18,FIND(" -",A18)-1))+TIME(0,30,0), "h:mm AM/PM") & " - " & TEXT(TIMEVALUE(MID(A18,FIND("- ",A18)+2,99))+TIME(0,30,0), "h:mm AM/PM") -> 12:00 PM - 12:30 PM | B19: 1 | C19: 1 | D19: 1 | E19: 1
A20: =TEXT(TIMEVALUE(LEFT(A19,FIND(" -",A19)-1))+TIME(0,30,0), "h:mm AM/PM") & " - " & TEXT(TIMEVALUE(MID(A19,FIND("- ",A19)+2,99))+TIME(0,30,0), "h:mm AM/PM") -> 12:30 PM - 1:00 PM | B20: 1 | C20: 1 | D20: 1 | E20: 1
A21: =TEXT(TIMEVALUE(LEFT(A20,FIND(" -",A20)-1))+TIME(0,30,0), "h:mm AM/PM") & " - " & TEXT(TIMEVALUE(MID(A20,FIND("- ",A20)+2,99))+TIME(0,30,0), "h:mm AM/PM") -> 1:00 PM - 1:30 PM | B21: 1 | C21: 1 | D21: 1 | E21: 1
A22: =TEXT(TIMEVALUE(LEFT(A21,FIND(" -",A21)-1))+TIME(0,30,0), "h:mm AM/PM") & " - " & TEXT(TIMEVALUE(MID(A21,FIND("- ",A21)+2,99))+TIME(0,30,0), "h:mm AM/PM") -> 1:30 PM - 2:00 PM | B22: 1 | C22: 1 | D22: 1 | E22: 1
A23: =TEXT(TIMEVALUE(LEFT(A22,FIND(" -",A22)-1))+TIME(0,30,0), "h:mm AM/PM") & " - " & TEXT(TIMEVALUE(MID(A22,FIND("- ",A22)+2,99))+TIME(0,30,0), "h:mm AM/PM") -> 2:00 PM - 2:30 PM | B23: 1 | C23: 1 | D23: 1 | E23: 1
A24: =TEXT(TIMEVALUE(LEFT(A23,FIND(" -",A23)-1))+TIME(0,30,0), "h:mm AM/PM") & " - " & TEXT(TIMEVALUE(MID(A23,FIND("- ",A23)+2,99))+TIME(0,30,0), "h:mm AM/PM") -> 2:30 PM - 3:00 PM | C24: 1 | D24: 1 | E24: 1
A25: =TEXT(TIMEVALUE(LEFT(A24,FIND(" -",A24)-1))+TIME(0,30,0), "h:mm AM/PM") & " - " & TEXT(TIMEVALUE(MID(A24,FIND("- ",A24)+2,99))+TIME(0,30,0), "h:mm AM/PM") -> 3:00 PM - 3:30 PM | C25: 1 | D25: 1 | E25: 1
A26: =TEXT(TIMEVALUE(LEFT(A25,FIND(" -",A25)-1))+TIME(0,30,0), "h:mm AM/PM") & " - " & TEXT(TIMEVALUE(MID(A25,FIND("- ",A25)+2,99))+TIME(0,30,0), "h:mm AM/PM") -> 3:30 PM - 4:00 PM | C26: 1 | D26: 1 | E26: 1
A27: =TEXT(TIMEVALUE(LEFT(A26,FIND(" -",A26)-1))+TIME(0,30,0), "h:mm AM/PM") & " - " & TEXT(TIMEVALUE(MID(A26,FIND("- ",A26)+2,99))+TIME(0,30,0), "h:mm AM/PM") -> 4:00 PM - 4:30 PM | C27: 1 | D27: 1 | E27: 1 | H27: 1
A28: =TEXT(TIMEVALUE(LEFT(A27,FIND(" -",A27)-1))+TIME(0,30,0), "h:mm AM/PM") & " - " & TEXT(TIMEVALUE(MID(A27,FIND("- ",A27)+2,99))+TIME(0,30,0), "h:mm AM/PM") -> 4:30 PM - 5:00 PM | C28: 1 | D28: 1 | E28: 1 | H28: 1
A29: =TEXT(TIMEVALUE(LEFT(A28,FIND(" -",A28)-1))+TIME(0,30,0), "h:mm AM/PM") & " - " & TEXT(TIMEVALUE(MID(A28,FIND("- ",A28)+2,99))+TIME(0,30,0), "h:mm AM/PM") -> 5:00 PM - 5:30 PM | D29: 1 | H29: 1
A30: =TEXT(TIMEVALUE(LEFT(A29,FIND(" -",A29)-1))+TIME(0,30,0), "h:mm AM/PM") & " - " & TEXT(TIMEVALUE(MID(A29,FIND("- ",A29)+2,99))+TIME(0,30,0), "h:mm AM/PM") -> 5:30 PM - 6:00 PM | D30: 1 | H30: 1
A31: =TEXT(TIMEVALUE(LEFT(A30,FIND(" -",A30)-1))+TIME(0,30,0), "h:mm AM/PM") & " - " & TEXT(TIMEVALUE(MID(A30,FIND("- ",A30)+2,99))+TIME(0,30,0), "h:mm AM/PM") -> 6:00 PM - 6:30 PM | D31: 1 | H31: 1
A32: =TEXT(TIMEVALUE(LEFT(A31,FIND(" -",A31)-1))+TIME(0,30,0), "h:mm AM/PM") & " - " & TEXT(TIMEVALUE(MID(A31,FIND("- ",A31)+2,99))+TIME(0,30,0), "h:mm AM/PM") -> 6:30 PM - 7:00 PM | D32: 1 | H32: 1
A33: =TEXT(TIMEVALUE(LEFT(A32,FIND(" -",A32)-1))+TIME(0,30,0), "h:mm AM/PM") & " - " & TEXT(TIMEVALUE(MID(A32,FIND("- ",A32)+2,99))+TIME(0,30,0), "h:mm AM/PM") -> 7:00 PM - 7:30 PM | D33: 1 | H33: 1
A34: =TEXT(TIMEVALUE(LEFT(A33,FIND(" -",A33)-1))+TIME(0,30,0), "h:mm AM/PM") & " - " & TEXT(TIMEVALUE(MID(A33,FIND("- ",A33)+2,99))+TIME(0,30,0), "h:mm AM/PM") -> 7:30 PM - 8:00 PM | D34: 1
A35: =TEXT(TIMEVALUE(LEFT(A34,FIND(" -",A34)-1))+TIME(0,30,0), "h:mm AM/PM") & " - " & TEXT(TIMEVALUE(MID(A34,FIND("- ",A34)+2,99))+TIME(0,30,0), "h:mm AM/PM") -> 8:00 PM - 8:30 PM | D35: 1
A36: =TEXT(TIMEVALUE(LEFT(A35,FIND(" -",A35)-1))+TIME(0,30,0), "h:mm AM/PM") & " - " & TEXT(TIMEVALUE(MID(A35,FIND("- ",A35)+2,99))+TIME(0,30,0), "h:mm AM/PM") -> 8:30 PM - 9:00 PM
A37: =TEXT(TIMEVALUE(LEFT(A36,FIND(" -",A36)-1))+TIME(0,30,0), "h:mm AM/PM") & " - " & TEXT(TIMEVALUE(MID(A36,FIND("- ",A36)+2,99))+TIME(0,30,0), "h:mm AM/PM") -> 9:00 PM - 9:30 PM
A38: =TEXT(TIMEVALUE(LEFT(A37,FIND(" -",A37)-1))+TIME(0,30,0), "h:mm AM/PM") & " - " & TEXT(TIMEVALUE(MID(A37,FIND("- ",A37)+2,99))+TIME(0,30,0), "h:mm AM/PM") -> 9:30 PM - 10:00 PM | F38: 1 | G38: 1
A39: =TEXT(TIMEVALUE(LEFT(A38,FIND(" -",A38)-1))+TIME(0,30,0), "h:mm AM/PM") & " - " & TEXT(TIMEVALUE(MID(A38,FIND("- ",A38)+2,99))+TIME(0,30,0), "h:mm AM/PM") -> 10:00 PM - 10:30 PM | F39: 1 | G39: 1
A40: =TEXT(TIMEVALUE(LEFT(A39,FIND(" -",A39)-1))+TIME(0,30,0), "h:mm AM/PM") & " - " & TEXT(TIMEVALUE(MID(A39,FIND("- ",A39)+2,99))+TIME(0,30,0), "h:mm AM/PM") -> 10:30 PM - 11:00 PM | B40: 1 | C40: 1 | D40: 1 | E40: 1 | F40: 1 | G40: 1 | H40: 1
A41: =TEXT(TIMEVALUE(LEFT(A40,FIND(" -",A40)-1))+TIME(0,30,0), "h:mm AM/PM") & " - " & TEXT(TIMEVALUE(MID(A40,FIND("- ",A40)+2,99))+TIME(0,30,0), "h:mm AM/PM") -> 11:00 PM - 11:30 PM | B41: 1 | C41: 1 | D41: 1 | E41: 1 | F41: 1 | G41: 1 | H41: 1
A42: =TEXT(TIMEVALUE(LEFT(A41,FIND(" -",A41)-1))+TIME(0,30,0), "h:mm AM/PM") & " - " & TEXT(TIMEVALUE(MID(A41,FIND("- ",A41)+2,99))+TIME(0,30,0), "h:mm AM/PM") -> 11:30 PM - 12:00 AM | B42: 1 | C42: 1 | D42: 1 | E42: 1 | F42: 1 | G42: 1 | H42: 1
...

Sheet Eva Huang
A1: Step 1: Rename the sheet name with your name, for example 'Member 4 Name' to 'Your Name' | J1: Time Zone
A2: Step 2: Choose your time zone from yellow drop down box | J2: PST
A3: Step 3: Enter '1' in all 30-minute slots you're NOT available in orange area | J3: {=_xlfn.SWITCH(J2,"PST",0,"MST",1,"CST",2,"EST",3,0)} -> 0
A6: Time | B6: Monday | C6: Tuesday | D6: Wednesday | E6: Thursday | F6: Friday | G6: Saturday | H6: Sunday
A7: =TEXT(TIME(3,0,0)+$J$3/24,"h:mm AM/PM") & " - " & TEXT(TIME(3,30,0)+$J$3/24,"h:mm AM/PM") -> 3:00 AM - 3:30 AM | B7: 1 | C7: 1 | D7: 1 | E7: 1 | F7: 1 | G7: 1 | H7: 1
A8: =TEXT(TIMEVALUE(LEFT(A7,FIND(" -",A7)-1))+TIME(0,30,0), "h:mm AM/PM") & " - " & TEXT(TIMEVALUE(MID(A7,FIND("- ",A7)+2,99))+TIME(0,30,0), "h:mm AM/PM") -> 3:30 AM - 4:00 AM | B8: 1 | C8: 1 | D8: 1 | E8: 1 | F8: 1 | G8: 1 | H8: 1
A9: =TEXT(TIMEVALUE(LEFT(A8,FIND(" -",A8)-1))+TIME(0,30,0), "h:mm AM/PM") & " - " & TEXT(TIMEVALUE(MID(A8,FIND("- ",A8)+2,99))+TIME(0,30,0), "h:mm AM/PM") -> 4:00 AM - 4:30 AM | B9: 1 | C9: 1 | D9: 1 | E9: 1 | F9: 1 | G9: 1 | H9: 1
A10: =TEXT(TIMEVALUE(LEFT(A9,FIND(" -",A9)-1))+TIME(0,30,0), "h:mm AM/PM") & " - " & TEXT(TIMEVALUE(MID(A9,FIND("- ",A9)+2,99))+TIME(0,30,0), "h:mm AM/PM") -> 4:30 AM - 5:00 AM | B10: 1 | C10: 1 | D10: 1 | E10: 1 | F10: 1 | G10: 1 | H10: 1
A11: =TEXT(TIMEVALUE(LEFT(A10,FIND(" -",A10)-1))+TIME(0,30,0), "h:mm AM/PM") & " - " & TEXT(TIMEVALUE(MID(A10,FIND("- ",A10)+2,99))+TIME(0,30,0), "h:mm AM/PM") -> 5:00 AM - 5:30 AM | B11: 1 | C11: 1 | D11: 1 | E11: 1 | F11: 1 | G11: 1 | H11: 1
A12: =TEXT(TIMEVALUE(LEFT(A11,FIND(" -",A11)-1))+TIME(0,30,0), "h:mm AM/PM") & " - " & TEXT(TIMEVALUE(MID(A11,FIND("- ",A11)+2,99))+TIME(0,30,0), "h:mm AM/PM") -> 5:30 AM - 6:00 AM | B12: 1 | C12: 1 | D12: 1 | E12: 1 | F12: 1 | G12: 1 | H12: 1
A13: =TEXT(TIMEVALUE(LEFT(A12,FIND(" -",A12)-1))+TIME(0,30,0), "h:mm AM/PM") & " - " & TEXT(TIMEVALUE(MID(A12,FIND("- ",A12)+2,99))+TIME(0,30,0), "h:mm AM/PM") -> 6:00 AM - 6:30 AM | B13: 1 | C13: 1 | D13: 1 | E13: 1 | F13: 1 | G13: 1 | H13: 1
A14: =TEXT(TIMEVALUE(LEFT(A13,FIND(" -",A13)-1))+TIME(0,30,0), "h:mm AM/PM") & " - " & TEXT(TIMEVALUE(MID(A13,FIND("- ",A13)+2,99))+TIME(0,30,0), "h:mm AM/PM") -> 6:30 AM - 7:00 AM | B14: 1 | C14: 1 | D14: 1 | E14: 1 | F14: 1 | G14: 1 | H14: 1
A15: =TEXT(TIMEVALUE(LEFT(A14,FIND(" -",A14)-1))+TIME(0,30,0), "h:mm AM/PM") & " - " & TEXT(TIMEVALUE(MID(A14,FIND("- ",A14)+2,99))+TIME(0,30,0), "h:mm AM/PM") -> 7:00 AM - 7:30 AM | B15: 1 | C15: 1 | D15: 1 | E15: 1 | F15: 1 | G15: 1 | H15: 1
A16: =TEXT(TIMEVALUE(LEFT(A15,FIND(" -",A15)-1))+TIME(0,30,0), "h:mm AM/PM") & " - " & TEXT(TIMEVALUE(MID(A15,FIND("- ",A15)+2,99))+TIME(0,30,0), "h:mm AM/PM") -> 7:30 AM - 8:00 AM | B16: 1 | C16: 1 | D16: 1 | E16: 1 | F16: 1 | G16: 1 | H16: 1
A17: =TEXT(TIMEVALUE(LEFT(A16,FIND(" -",A16)-1))+TIME(0,30,0), "h:mm AM/PM") & " - " & TEXT(TIMEVALUE(MID(A16,FIND("- ",A16)+2,99))+TIME(0,30,0), "h:mm AM/PM") -> 8:00 AM - 8:30 AM | B17: 1 | C17: 1 | D17: 1 | E17: 1 | F17: 1 | G17: 1 | H17: 1
A18: =TEXT(TIMEVALUE(LEFT(A17,FIND(" -",A17)-1))+TIME(0,30,0), "h:mm AM/PM") & " - " & TEXT(TIMEVALUE(MID(A17,FIND("- ",A17)+2,99))+TIME(0,30,0), "h:mm AM/PM") -> 8:30 AM - 9:00 AM | B18: 1 | C18: 1 | D18: 1 | E18: 1 | F18: 1 | G18: 1 | H18: 1
A19: =TEXT(TIMEVALUE(LEFT(A18,FIND(" -",A18)-1))+TIME(0,30,0), "h:mm AM/PM") & " - " & TEXT(TIMEVALUE(MID(A18,FIND("- ",A18)+2,99))+TIME(0,30,0), "h:mm AM/PM") -> 9:00 AM - 9:30 AM | B19: 1 | C19: 1 | D19: 1 | E19: 1 | F19: 1 | G19: 1 | H19: 1
A20: =TEXT(TIMEVALUE(LEFT(A19,FIND(" -",A19)-1))+TIME(0,30,0), "h:mm AM/PM") & " - " & TEXT(TIMEVALUE(MID(A19,FIND("- ",A19)+2,99))+TIME(0,30,0), "h:mm AM/PM") -> 9:30 AM - 10:00 AM
A21: =TEXT(TIMEVALUE(LEFT(A20,FIND(" -",A20)-1))+TIME(0,30,0), "h:mm AM/PM") & " - " & TEXT(TIMEVALUE(MID(A20,FIND("- ",A20)+2,99))+TIME(0,30,0), "h:mm AM/PM") -> 10:00 AM - 10:30 AM
A22: =TEXT(TIMEVALUE(LEFT(A21,FIND(" -",A21)-1))+TIME(0,30,0), "h:mm AM/PM") & " - " & TEXT(TIMEVALUE(MID(A21,FIND("- ",A21)+2,99))+TIME(0,30,0), "h:mm AM/PM") -> 10:30 AM - 11:00 AM
A23: =TEXT(TIMEVALUE(LEFT(A22,FIND(" -",A22)-1))+TIME(0,30,0), "h:mm AM/PM") & " - " & TEXT(TIMEVALUE(MID(A22,FIND("- ",A22)+2,99))+TIME(0,30,0), "h:mm AM/PM") -> 11:00 AM - 11:30 AM | C23: 1 | E23: 1
A24: =TEXT(TIMEVALUE(LEFT(A23,FIND(" -",A23)-1))+TIME(0,30,0), "h:mm AM/PM") & " - " & TEXT(TIMEVALUE(MID(A23,FIND("- ",A23)+2,99))+TIME(0,30,0), "h:mm AM/PM") -> 11:30 AM - 12:00 PM | C24: 1 | E24: 1
A25: =TEXT(TIMEVALUE(LEFT(A24,FIND(" -",A24)-1))+TIME(0,30,0), "h:mm AM/PM") & " - " & TEXT(TIMEVALUE(MID(A24,FIND("- ",A24)+2,99))+TIME(0,30,0), "h:mm AM/PM") -> 12:00 PM - 12:30 PM | C25: 1 | E25: 1
A26: =TEXT(TIMEVALUE(LEFT(A25,FIND(" -",A25)-1))+TIME(0,30,0), "h:mm AM/PM") & " - " & TEXT(TIMEVALUE(MID(A25,FIND("- ",A25)+2,99))+TIME(0,30,0), "h:mm AM/PM") -> 12:30 PM - 1:00 PM | C26: 1 | E26: 1
A27: =TEXT(TIMEVALUE(LEFT(A26,FIND(" -",A26)-1))+TIME(0,30,0), "h:mm AM/PM") & " - " & TEXT(TIMEVALUE(MID(A26,FIND("- ",A26)+2,99))+TIME(0,30,0), "h:mm AM/PM") -> 1:00 PM - 1:30 PM | C27: 1 | E27: 1
A28: =TEXT(TIMEVALUE(LEFT(A27,FIND(" -",A27)-1))+TIME(0,30,0), "h:mm AM/PM") & " - " & TEXT(TIMEVALUE(MID(A27,FIND("- ",A27)+2,99))+TIME(0,30,0), "h:mm AM/PM") -> 1:30 PM - 2:00 PM | C28: 1 | E28: 1
A29: =TEXT(TIMEVALUE(LEFT(A28,FIND(" -",A28)-1))+TIME(0,30,0), "h:mm AM/PM") & " - " & TEXT(TIMEVALUE(MID(A28,FIND("- ",A28)+2,99))+TIME(0,30,0), "h:mm AM/PM") -> 2:00 PM - 2:30 PM | B29: 1 | C29: 1 | D29: 1 | E29: 1
A30: =TEXT(TIMEVALUE(LEFT(A29,FIND(" -",A29)-1))+TIME(0,30,0), "h:mm AM/PM") & " - " & TEXT(TIMEVALUE(MID(A29,FIND("- ",A29)+2,99))+TIME(0,30,0), "h:mm AM/PM") -> 2:30 PM - 3:00 PM | B30: 1 | C30: 1 | D30: 1 | E30: 1
A31: =TEXT(TIMEVALUE(LEFT(A30,FIND(" -",A30)-1))+TIME(0,30,0), "h:mm AM/PM") & " - " & TEXT(TIMEVALUE(MID(A30,FIND("- ",A30)+2,99))+TIME(0,30,0), "h:mm AM/PM") -> 3:00 PM - 3:30 PM | B31: 1 | C31: 1 | D31: 1 | E31: 1
A32: =TEXT(TIMEVALUE(LEFT(A31,FIND(" -",A31)-1))+TIME(0,30,0), "h:mm AM/PM") & " - " & TEXT(TIMEVALUE(MID(A31,FIND("- ",A31)+2,99))+TIME(0,30,0), "h:mm AM/PM") -> 3:30 PM - 4:00 PM | B32: 1 | C32: 1 | D32: 1 | E32: 1
A33: =TEXT(TIMEVALUE(LEFT(A32,FIND(" -",A32)-1))+TIME(0,30,0), "h:mm AM/PM") & " - " & TEXT(TIMEVALUE(MID(A32,FIND("- ",A32)+2,99))+TIME(0,30,0), "h:mm AM/PM") -> 4:00 PM - 4:30 PM | B33: 1 | C33: 1 | D33: 1 | E33: 1
A34: =TEXT(TIMEVALUE(LEFT(A33,FIND(" -",A33)-1))+TIME(0,30,0), "h:mm AM/PM") & " - " & TEXT(TIMEVALUE(MID(A33,FIND("- ",A33)+2,99))+TIME(0,30,0), "h:mm AM/PM") -> 4:30 PM - 5:00 PM | B34: 1 | D34: 1
A35: =TEXT(TIMEVALUE(LEFT(A34,FIND(" -",A34)-1))+TIME(0,30,0), "h:mm AM/PM") & " - " & TEXT(TIMEVALUE(MID(A34,FIND("- ",A34)+2,99))+TIME(0,30,0), "h:mm AM/PM") -> 5:00 PM - 5:30 PM | B35: 1 | D35: 1
A36: =TEXT(TIMEVALUE(LEFT(A35,FIND(" -",A35)-1))+TIME(0,30,0), "h:mm AM/PM") & " - " & TEXT(TIMEVALUE(MID(A35,FIND("- ",A35)+2,99))+TIME(0,30,0), "h:mm AM/PM") -> 5:30 PM - 6:00 PM
A37: =TEXT(TIMEVALUE(LEFT(A36,FIND(" -",A36)-1))+TIME(0,30,0), "h:mm AM/PM") & " - " & TEXT(TIMEVALUE(MID(A36,FIND("- ",A36)+2,99))+TIME(0,30,0), "h:mm AM/PM") -> 6:00 PM - 6:30 PM
A38: =TEXT(TIMEVALUE(LEFT(A37,FIND(" -",A37)-1))+TIME(0,30,0), "h:mm AM/PM") & " - " & TEXT(TIMEVALUE(MID(A37,FIND("- ",A37)+2,99))+TIME(0,30,0), "h:mm AM/PM") -> 6:30 PM - 7:00 PM
A39: =TEXT(TIMEVALUE(LEFT(A38,FIND(" -",A38)-1))+TIME(0,30,0), "h:mm AM/PM") & " - " & TEXT(TIMEVALUE(MID(A38,FIND("- ",A38)+2,99))+TIME(0,30,0), "h:mm AM/PM") -> 7:00 PM - 7:30 PM
A40: =TEXT(TIMEVALUE(LEFT(A39,FIND(" -",A39)-1))+TIME(0,30,0), "h:mm AM/PM") & " - " & TEXT(TIMEVALUE(MID(A39,FIND("- ",A39)+2,99))+TIME(0,30,0), "h:mm AM/PM") -> 7:30 PM - 8:00 PM
A41: =TEXT(TIMEVALUE(LEFT(A40,FIND(" -",A40)-1))+TIME(0,30,0), "h:mm AM/PM") & " - " & TEXT(TIMEVALUE(MID(A40,FIND("- ",A40)+2,99))+TIME(0,30,0), "h:mm AM/PM") -> 8:00 PM - 8:30 PM
A42: =TEXT(TIMEVALUE(LEFT(A41,FIND(" -",A41)-1))+TIME(0,30,0), "h:mm AM/PM") & " - " & TEXT(TIMEVALUE(MID(A41,FIND("- ",A41)+2,99))+TIME(0,30,0), "h:mm AM/PM") -> 8:30 PM - 9:00 PM
...

Sheet Yuki Saeli
A1: Step 1: Rename the sheet name with your name, for example 'Member 5 Name' to 'Your Name' | J1: Time Zone
A2: Step 2: Choose your time zone from yellow drop down box | J2: PST
A3: Step 3: Enter '1' in all 30-minute slots you're NOT available in orange area | J3: {=_xlfn.SWITCH(J2,"PST",0,"MST",1,"CST",2,"EST",3,0)} -> 0
A6: Time | B6: Monday | C6: Tuesday | D6: Wednesday | E6: Thursday | F6: Friday | G6: Saturday | H6: Sunday
A7: =TEXT(TIME(3,0,0)+$J$3/24,"h:mm AM/PM") & " - " & TEXT(TIME(3,30,0)+$J$3/24,"h:mm AM/PM") -> 3:00 AM - 3:30 AM | B7: 1 | C7: 1 | D7: 1 | E7: 1 | F7: 1 | G7: 1 | H7: 1
A8: =TEXT(TIMEVALUE(LEFT(A7,FIND(" -",A7)-1))+TIME(0,30,0), "h:mm AM/PM") & " - " & TEXT(TIMEVALUE(MID(A7,FIND("- ",A7)+2,99))+TIME(0,30,0), "h:mm AM/PM") -> 3:30 AM - 4:00 AM | B8: 1 | C8: 1 | D8: 1 | E8: 1 | F8: 1 | G8: 1 | H8: 1
A9: =TEXT(TIMEVALUE(LEFT(A8,FIND(" -",A8)-1))+TIME(0,30,0), "h:mm AM/PM") & " - " & TEXT(TIMEVALUE(MID(A8,FIND("- ",A8)+2,99))+TIME(0,30,0), "h:mm AM/PM") -> 4:00 AM - 4:30 AM | B9: 1 | C9: 1 | D9: 1 | E9: 1 | F9: 1 | G9: 1 | H9: 1
A10: =TEXT(TIMEVALUE(LEFT(A9,FIND(" -",A9)-1))+TIME(0,30,0), "h:mm AM/PM") & " - " & TEXT(TIMEVALUE(MID(A9,FIND("- ",A9)+2,99))+TIME(0,30,0), "h:mm AM/PM") -> 4:30 AM - 5:00 AM | B10: 1 | C10: 1 | D10: 1 | E10: 1 | F10: 1 | G10: 1 | H10: 1
A11: =TEXT(TIMEVALUE(LEFT(A10,FIND(" -",A10)-1))+TIME(0,30,0), "h:mm AM/PM") & " - " & TEXT(TIMEVALUE(MID(A10,FIND("- ",A10)+2,99))+TIME(0,30,0), "h:mm AM/PM") -> 5:00 AM - 5:30 AM | B11: 1 | C11: 1 | D11: 1 | E11: 1 | F11: 1 | G11: 1 | H11: 1
A12: =TEXT(TIMEVALUE(LEFT(A11,FIND(" -",A11)-1))+TIME(0,30,0), "h:mm AM/PM") & " - " & TEXT(TIMEVALUE(MID(A11,FIND("- ",A11)+2,99))+TIME(0,30,0), "h:mm AM/PM") -> 5:30 AM - 6:00 AM | B12: 1 | C12: 1 | D12: 1 | E12: 1 | F12: 1 | G12: 1 | H12: 1
A13: =TEXT(TIMEVALUE(LEFT(A12,FIND(" -",A12)-1))+TIME(0,30,0), "h:mm AM/PM") & " - " & TEXT(TIMEVALUE(MID(A12,FIND("- ",A12)+2,99))+TIME(0,30,0), "h:mm AM/PM") -> 6:00 AM - 6:30 AM | B13: 1 | C13: 1 | D13: 1 | E13: 1 | F13: 1 | G13: 1 | H13: 1
A14: =TEXT(TIMEVALUE(LEFT(A13,FIND(" -",A13)-1))+TIME(0,30,0), "h:mm AM/PM") & " - " & TEXT(TIMEVALUE(MID(A13,FIND("- ",A13)+2,99))+TIME(0,30,0), "h:mm AM/PM") -> 6:30 AM - 7:00 AM | B14: 1 | C14: 1 | D14: 1 | E14: 1 | F14: 1 | G14: 1 | H14: 1
A15: =TEXT(TIMEVALUE(LEFT(A14,FIND(" -",A14)-1))+TIME(0,30,0), "h:mm AM/PM") & " - " & TEXT(TIMEVALUE(MID(A14,FIND("- ",A14)+2,99))+TIME(0,30,0), "h:mm AM/PM") -> 7:00 AM - 7:30 AM | B15: 1 | C15: 1 | D15: 1 | E15: 1 | F15: 1 | G15: 1 | H15: 1
A16: =TEXT(TIMEVALUE(LEFT(A15,FIND(" -",A15)-1))+TIME(0,30,0), "h:mm AM/PM") & " - " & TEXT(TIMEVALUE(MID(A15,FIND("- ",A15)+2,99))+TIME(0,30,0), "h:mm AM/PM") -> 7:30 AM - 8:00 AM | B16: 1 | C16: 1 | D16: 1 | E16: 1 | F16: 1 | G16: 1 | H16: 1
A17: =TEXT(TIMEVALUE(LEFT(A16,FIND(" -",A16)-1))+TIME(0,30,0), "h:mm AM/PM") & " - " & TEXT(TIMEVALUE(MID(A16,FIND("- ",A16)+2,99))+TIME(0,30,0), "h:mm AM/PM") -> 8:00 AM - 8:30 AM
A18: =TEXT(TIMEVALUE(LEFT(A17,FIND(" -",A17)-1))+TIME(0,30,0), "h:mm AM/PM") & " - " & TEXT(TIMEVALUE(MID(A17,FIND("- ",A17)+2,99))+TIME(0,30,0), "h:mm AM/PM") -> 8:30 AM - 9:00 AM
A19: =TEXT(TIMEVALUE(LEFT(A18,FIND(" -",A18)-1))+TIME(0,30,0), "h:mm AM/PM") & " - " & TEXT(TIMEVALUE(MID(A18,FIND("- ",A18)+2,99))+TIME(0,30,0), "h:mm AM/PM") -> 9:00 AM - 9:30 AM
A20: =TEXT(TIMEVALUE(LEFT(A19,FIND(" -",A19)-1))+TIME(0,30,0), "h:mm AM/PM") & " - " & TEXT(TIMEVALUE(MID(A19,FIND("- ",A19)+2,99))+TIME(0,30,0), "h:mm AM/PM") -> 9:30 AM - 10:00 AM | B20: 1 | C20: 1 | D20: 1 | E20: 1 | F20: 1
A21: =TEXT(TIMEVALUE(LEFT(A20,FIND(" -",A20)-1))+TIME(0,30,0), "h:mm AM/PM") & " - " & TEXT(TIMEVALUE(MID(A20,FIND("- ",A20)+2,99))+TIME(0,30,0), "h:mm AM/PM") -> 10:00 AM - 10:30 AM | B21: 1 | C21: 1 | D21: 1 | E21: 1 | F21: 1
A22: =TEXT(TIMEVALUE(LEFT(A21,FIND(" -",A21)-1))+TIME(0,30,0), "h:mm AM/PM") & " - " & TEXT(TIMEVALUE(MID(A21,FIND("- ",A21)+2,99))+TIME(0,30,0), "h:mm AM/PM") -> 10:30 AM - 11:00 AM | B22: 1 | C22: 1 | D22: 1 | E22: 1 | F22: 1
A23: =TEXT(TIMEVALUE(LEFT(A22,FIND(" -",A22)-1))+TIME(0,30,0), "h:mm AM/PM") & " - " & TEXT(TIMEVALUE(MID(A22,FIND("- ",A22)+2,99))+TIME(0,30,0), "h:mm AM/PM") -> 11:00 AM - 11:30 AM | B23: 1 | D23: 1 | F23: 1
A24: =TEXT(TIMEVALUE(LEFT(A23,FIND(" -",A23)-1))+TIME(0,30,0), "h:mm AM/PM") & " - " & TEXT(TIMEVALUE(MID(A23,FIND("- ",A23)+2,99))+TIME(0,30,0), "h:mm AM/PM") -> 11:30 AM - 12:00 PM | B24: 1 | D24: 1 | F24: 1
A25: =TEXT(TIMEVALUE(LEFT(A24,FIND(" -",A24)-1))+TIME(0,30,0), "h:mm AM/PM") & " - " & TEXT(TIMEVALUE(MID(A24,FIND("- ",A24)+2,99))+TIME(0,30,0), "h:mm AM/PM") -> 12:00 PM - 12:30 PM | B25: 1 | D25: 1 | F25: 1
A26: =TEXT(TIMEVALUE(LEFT(A25,FIND(" -",A25)-1))+TIME(0,30,0), "h:mm AM/PM") & " - " & TEXT(TIMEVALUE(MID(A25,FIND("- ",A25)+2,99))+TIME(0,30,0), "h:mm AM/PM") -> 12:30 PM - 1:00 PM | B26: 1 | C26: 1 | D26: 1 | E26: 1 | F26: 1
A27: =TEXT(TIMEVALUE(LEFT(A26,FIND(" -",A26)-1))+TIME(0,30,0), "h:mm AM/PM") & " - " & TEXT(TIMEVALUE(MID(A26,FIND("- ",A26)+2,99))+TIME(0,30,0), "h:mm AM/PM") -> 1:00 PM - 1:30 PM | B27: 1 | C27: 1 | D27: 1 | E27: 1 | F27: 1
A28: =TEXT(TIMEVALUE(LEFT(A27,FIND(" -",A27)-1))+TIME(0,30,0), "h:mm AM/PM") & " - " & TEXT(TIMEVALUE(MID(A27,FIND("- ",A27)+2,99))+TIME(0,30,0), "h:mm AM/PM") -> 1:30 PM - 2:00 PM | B28: 1 | C28: 1 | D28: 1 | E28: 1 | F28: 1
A29: =TEXT(TIMEVALUE(LEFT(A28,FIND(" -",A28)-1))+TIME(0,30,0), "h:mm AM/PM") & " - " & TEXT(TIMEVALUE(MID(A28,FIND("- ",A28)+2,99))+TIME(0,30,0), "h:mm AM/PM") -> 2:00 PM - 2:30 PM | F29: 1
A30: =TEXT(TIMEVALUE(LEFT(A29,FIND(" -",A29)-1))+TIME(0,30,0), "h:mm AM/PM") & " - " & TEXT(TIMEVALUE(MID(A29,FIND("- ",A29)+2,99))+TIME(0,30,0), "h:mm AM/PM") -> 2:30 PM - 3:00 PM | F30: 1
A31: =TEXT(TIMEVALUE(LEFT(A30,FIND(" -",A30)-1))+TIME(0,30,0), "h:mm AM/PM") & " - " & TEXT(TIMEVALUE(MID(A30,FIND("- ",A30)+2,99))+TIME(0,30,0), "h:mm AM/PM") -> 3:00 PM - 3:30 PM
A32: =TEXT(TIMEVALUE(LEFT(A31,FIND(" -",A31)-1))+TIME(0,30,0), "h:mm AM/PM") & " - " & TEXT(TIMEVALUE(MID(A31,FIND("- ",A31)+2,99))+TIME(0,30,0), "h:mm AM/PM") -> 3:30 PM - 4:00 PM
A33: =TEXT(TIMEVALUE(LEFT(A32,FIND(" -",A32)-1))+TIME(0,30,0), "h:mm AM/PM") & " - " & TEXT(TIMEVALUE(MID(A32,FIND("- ",A32)+2,99))+TIME(0,30,0), "h:mm AM/PM") -> 4:00 PM - 4:30 PM
A34: =TEXT(TIMEVALUE(LEFT(A33,FIND(" -",A33)-1))+TIME(0,30,0), "h:mm AM/PM") & " - " & TEXT(TIMEVALUE(MID(A33,FIND("- ",A33)+2,99))+TIME(0,30,0), "h:mm AM/PM") -> 4:30 PM - 5:00 PM
A35: =TEXT(TIMEVALUE(LEFT(A34,FIND(" -",A34)-1))+TIME(0,30,0), "h:mm AM/PM") & " - " & TEXT(TIMEVALUE(MID(A34,FIND("- ",A34)+2,99))+TIME(0,30,0), "h:mm AM/PM") -> 5:00 PM - 5:30 PM | D35: 1 | E35: 1 | F35: 1
A36: =TEXT(TIMEVALUE(LEFT(A35,FIND(" -",A35)-1))+TIME(0,30,0), "h:mm AM/PM") & " - " & TEXT(TIMEVALUE(MID(A35,FIND("- ",A35)+2,99))+TIME(0,30,0), "h:mm AM/PM") -> 5:30 PM - 6:00 PM | D36: 1 | E36: 1 | F36: 1
A37: =TEXT(TIMEVALUE(LEFT(A36,FIND(" -",A36)-1))+TIME(0,30,0), "h:mm AM/PM") & " - " & TEXT(TIMEVALUE(MID(A36,FIND("- ",A36)+2,99))+TIME(0,30,0), "h:mm AM/PM") -> 6:00 PM - 6:30 PM
A38: =TEXT(TIMEVALUE(LEFT(A37,FIND(" -",A37)-1))+TIME(0,30,0), "h:mm AM/PM") & " - " & TEXT(TIMEVALUE(MID(A37,FIND("- ",A37)+2,99))+TIME(0,30,0), "h:mm AM/PM") -> 6:30 PM - 7:00 PM
A39: =TEXT(TIMEVALUE(LEFT(A38,FIND(" -",A38)-1))+TIME(0,30,0), "h:mm AM/PM") & " - " & TEXT(TIMEVALUE(MID(A38,FIND("- ",A38)+2,99))+TIME(0,30,0), "h:mm AM/PM") -> 7:00 PM - 7:30 PM
A40: =TEXT(TIMEVALUE(LEFT(A39,FIND(" -",A39)-1))+TIME(0,30,0), "h:mm AM/PM") & " - " & TEXT(TIMEVALUE(MID(A39,FIND("- ",A39)+2,99))+TIME(0,30,0), "h:mm AM/PM") -> 7:30 PM - 8:00 PM
A41: =TEXT(TIMEVALUE(LEFT(A40,FIND(" -",A40)-1))+TIME(0,30,0), "h:mm AM/PM") & " - " & TEXT(TIMEVALUE(MID(A40,FIND("- ",A40)+2,99))+TIME(0,30,0), "h:mm AM/PM") -> 8:00 PM - 8:30 PM
A42: =TEXT(TIMEVALUE(LEFT(A41,FIND(" -",A41)-1))+TIME(0,30,0), "h:mm AM/PM") & " - " & TEXT(TIMEVALUE(MID(A41,FIND("- ",A41)+2,99))+TIME(0,30,0), "h:mm AM/PM") -> 8:30 PM - 9:00 PM
...

Sheet Team Availability
A1: Step 1. Choose your time zone from yellow drop down box | J1: Time Zone
J2: PST
A3: The darker the cell, the more people are available. Black cells mean all members are free to meet. | J3: {=_xlfn.SWITCH(J2,"PST",0,"MST",1,"CST",2,"EST",3,0)} -> 0
A6: Time | B6: Monday | C6: Tuesday | D6: Wednesday | E6: Thursday | F6: Friday | G6: Saturday | H6: Sunday
A7: =TEXT(TIME(3,0,0)+$J$3/24,"h:mm AM/PM") & " - " & TEXT(TIME(3,30,0)+$J$3/24,"h:mm AM/PM") -> 3:00 AM - 3:30 AM | B7: =IF(COUNTA('Jaycie Liu'!B7,'Orson Lee'!B7,'Maria Herrmann'!B7,'Eva Huang'!B7,'Yuki Saeli'!B7)=0,0,COUNTA('Jaycie Liu'!B7,'Orson Lee'!B7,'Maria Herrmann'!B7,'Eva Huang'!B7,'Yuki Saeli'!B7)) -> 5 | C7: =IF(COUNTA('Jaycie Liu'!C7,'Orson Lee'!C7,'Maria Herrmann'!C7,'Eva Huang'!C7,'Yuki Saeli'!C7)=0,0,COUNTA('Jaycie Liu'!C7,'Orson Lee'!C7,'Maria Herrmann'!C7,'Eva Huang'!C7,'Yuki Saeli'!C7)) -> 5 | D7: =IF(COUNTA('Jaycie Liu'!D7,'Orson Lee'!D7,'Maria Herrmann'!D7,'Eva Huang'!D7,'Yuki Saeli'!D7)=0,0,COUNTA('Jaycie Liu'!D7,'Orson Lee'!D7,'Maria Herrmann'!D7,'Eva Huang'!D7,'Yuki Saeli'!D7)) -> 5 | E7: =IF(COUNTA('Jaycie Liu'!E7,'Orson Lee'!E7,'Maria Herrmann'!E7,'Eva Huang'!E7,'Yuki Saeli'!E7)=0,0,COUNTA('Jaycie Liu'!E7,'Orson Lee'!E7,'Maria Herrmann'!E7,'Eva Huang'!E7,'Yuki Saeli'!E7)) -> 5 | F7: =IF(COUNTA('Jaycie Liu'!F7,'Orson Lee'!F7,'Maria Herrmann'!F7,'Eva Huang'!F7,'Yuki Saeli'!F7)=0,0,COUNTA('Jaycie Liu'!F7,'Orson Lee'!F7,'Maria Herrmann'!F7,'Eva Huang'!F7,'Yuki Saeli'!F7)) -> 5 | G7: =IF(COUNTA('Jaycie Liu'!G7,'Orson Lee'!G7,'Maria Herrmann'!G7,'Eva Huang'!G7,'Yuki Saeli'!G7)=0,0,COUNTA('Jaycie Liu'!G7,'Orson Lee'!G7,'Maria Herrmann'!G7,'Eva Huang'!G7,'Yuki Saeli'!G7)) -> 5 | H7: =IF(COUNTA('Jaycie Liu'!H7,'Orson Lee'!H7,'Maria Herrmann'!H7,'Eva Huang'!H7,'Yuki Saeli'!H7)=0,0,COUNTA('Jaycie Liu'!H7,'Orson Lee'!H7,'Maria Herrmann'!H7,'Eva Huang'!H7,'Yuki Saeli'!H7)) -> 5
A8: =TEXT(TIMEVALUE(LEFT(A7,FIND(" -",A7)-1))+TIME(0,30,0), "h:mm AM/PM") & " - " & TEXT(TIMEVALUE(MID(A7,FIND("- ",A7)+2,99))+TIME(0,30,0), "h:mm AM/PM") -> 3:30 AM - 4:00 AM | B8: =IF(COUNTA('Jaycie Liu'!B8,'Orson Lee'!B8,'Maria Herrmann'!B8,'Eva Huang'!B8,'Yuki Saeli'!B8)=0,0,COUNTA('Jaycie Liu'!B8,'Orson Lee'!B8,'Maria Herrmann'!B8,'Eva Huang'!B8,'Yuki Saeli'!B8)) -> 5 | C8: =IF(COUNTA('Jaycie Liu'!C8,'Orson Lee'!C8,'Maria Herrmann'!C8,'Eva Huang'!C8,'Yuki Saeli'!C8)=0,0,COUNTA('Jaycie Liu'!C8,'Orson Lee'!C8,'Maria Herrmann'!C8,'Eva Huang'!C8,'Yuki Saeli'!C8)) -> 5 | D8: =IF(COUNTA('Jaycie Liu'!D8,'Orson Lee'!D8,'Maria Herrmann'!D8,'Eva Huang'!D8,'Yuki Saeli'!D8)=0,0,COUNTA('Jaycie Liu'!D8,'Orson Lee'!D8,'Maria Herrmann'!D8,'Eva Huang'!D8,'Yuki Saeli'!D8)) -> 5 | E8: =IF(COUNTA('Jaycie Liu'!E8,'Orson Lee'!E8,'Maria Herrmann'!E8,'Eva Huang'!E8,'Yuki Saeli'!E8)=0,0,COUNTA('Jaycie Liu'!E8,'Orson Lee'!E8,'Maria Herrmann'!E8,'Eva Huang'!E8,'Yuki Saeli'!E8)) -> 5 | F8: =IF(COUNTA('Jaycie Liu'!F8,'Orson Lee'!F8,'Maria Herrmann'!F8,'Eva Huang'!F8,'Yuki Saeli'!F8)=0,0,COUNTA('Jaycie Liu'!F8,'Orson Lee'!F8,'Maria Herrmann'!F8,'Eva Huang'!F8,'Yuki Saeli'!F8)) -> 5 | G8: =IF(COUNTA('Jaycie Liu'!G8,'Orson Lee'!G8,'Maria Herrmann'!G8,'Eva Huang'!G8,'Yuki Saeli'!G8)=0,0,COUNTA('Jaycie Liu'!G8,'Orson Lee'!G8,'Maria Herrmann'!G8,'Eva Huang'!G8,'Yuki Saeli'!G8)) -> 5 | H8: =IF(COUNTA('Jaycie Liu'!H8,'Orson Lee'!H8,'Maria Herrmann'!H8,'Eva Huang'!H8,'Yuki Saeli'!H8)=0,0,COUNTA('Jaycie Liu'!H8,'Orson Lee'!H8,'Maria Herrmann'!H8,'Eva Huang'!H8,'Yuki Saeli'!H8)) -> 5
A9: =TEXT(TIMEVALUE(LEFT(A8,FIND(" -",A8)-1))+TIME(0,30,0), "h:mm AM/PM") & " - " & TEXT(TIMEVALUE(MID(A8,FIND("- ",A8)+2,99))+TIME(0,30,0), "h:mm AM/PM") -> 4:00 AM - 4:30 AM | B9: =IF(COUNTA('Jaycie Liu'!B9,'Orson Lee'!B9,'Maria Herrmann'!B9,'Eva Huang'!B9,'Yuki Saeli'!B9)=0,0,COUNTA('Jaycie Liu'!B9,'Orson Lee'!B9,'Maria Herrmann'!B9,'Eva Huang'!B9,'Yuki Saeli'!B9)) -> 5 | C9: =IF(COUNTA('Jaycie Liu'!C9,'Orson Lee'!C9,'Maria Herrmann'!C9,'Eva Huang'!C9,'Yuki Saeli'!C9)=0,0,COUNTA('Jaycie Liu'!C9,'Orson Lee'!C9,'Maria Herrmann'!C9,'Eva Huang'!C9,'Yuki Saeli'!C9)) -> 5 | D9: =IF(COUNTA('Jaycie Liu'!D9,'Orson Lee'!D9,'Maria Herrmann'!D9,'Eva Huang'!D9,'Yuki Saeli'!D9)=0,0,COUNTA('Jaycie Liu'!D9,'Orson Lee'!D9,'Maria Herrmann'!D9,'Eva Huang'!D9,'Yuki Saeli'!D9)) -> 5 | E9: =IF(COUNTA('Jaycie Liu'!E9,'Orson Lee'!E9,'Maria Herrmann'!E9,'Eva Huang'!E9,'Yuki Saeli'!E9)=0,0,COUNTA('Jaycie Liu'!E9,'Orson Lee'!E9,'Maria Herrmann'!E9,'Eva Huang'!E9,'Yuki Saeli'!E9)) -> 5 | F9: =IF(COUNTA('Jaycie Liu'!F9,'Orson Lee'!F9,'Maria Herrmann'!F9,'Eva Huang'!F9,'Yuki Saeli'!F9)=0,0,COUNTA('Jaycie Liu'!F9,'Orson Lee'!F9,'Maria Herrmann'!F9,'Eva Huang'!F9,'Yuki Saeli'!F9)) -> 5 | G9: =IF(COUNTA('Jaycie Liu'!G9,'Orson Lee'!G9,'Maria Herrmann'!G9,'Eva Huang'!G9,'Yuki Saeli'!G9)=0,0,COUNTA('Jaycie Liu'!G9,'Orson Lee'!G9,'Maria Herrmann'!G9,'Eva Huang'!G9,'Yuki Saeli'!G9)) -> 5 | H9: =IF(COUNTA('Jaycie Liu'!H9,'Orson Lee'!H9,'Maria Herrmann'!H9,'Eva Huang'!H9,'Yuki Saeli'!H9)=0,0,COUNTA('Jaycie Liu'!H9,'Orson Lee'!H9,'Maria Herrmann'!H9,'Eva Huang'!H9,'Yuki Saeli'!H9)) -> 5
A10: =TEXT(TIMEVALUE(LEFT(A9,FIND(" -",A9)-1))+TIME(0,30,0), "h:mm AM/PM") & " - " & TEXT(TIMEVALUE(MID(A9,FIND("- ",A9)+2,99))+TIME(0,30,0), "h:mm AM/PM") -> 4:30 AM - 5:00 AM | B10: =IF(COUNTA('Jaycie Liu'!B10,'Orson Lee'!B10,'Maria Herrmann'!B10,'Eva Huang'!B10,'Yuki Saeli'!B10)=0,0,COUNTA('Jaycie Liu'!B10,'Orson Lee'!B10,'Maria Herrmann'!B10,'Eva Huang'!B10,'Yuki Saeli'!B10)) -> 5 | C10: =IF(COUNTA('Jaycie Liu'!C10,'Orson Lee'!C10,'Maria Herrmann'!C10,'Eva Huang'!C10,'Yuki Saeli'!C10)=0,0,COUNTA('Jaycie Liu'!C10,'Orson Lee'!C10,'Maria Herrmann'!C10,'Eva Huang'!C10,'Yuki Saeli'!C10)) -> 5 | D10: =IF(COUNTA('Jaycie Liu'!D10,'Orson Lee'!D10,'Maria Herrmann'!D10,'Eva Huang'!D10,'Yuki Saeli'!D10)=0,0,COUNTA('Jaycie Liu'!D10,'Orson Lee'!D10,'Maria Herrmann'!D10,'Eva Huang'!D10,'Yuki Saeli'!D10)) -> 5 | E10: =IF(COUNTA('Jaycie Liu'!E10,'Orson Lee'!E10,'Maria Herrmann'!E10,'Eva Huang'!E10,'Yuki Saeli'!E10)=0,0,COUNTA('Jaycie Liu'!E10,'Orson Lee'!E10,'Maria Herrmann'!E10,'Eva Huang'!E10,'Yuki Saeli'!E10)) -> 5 | F10: =IF(COUNTA('Jaycie Liu'!F10,'Orson Lee'!F10,'Maria Herrmann'!F10,'Eva Huang'!F10,'Yuki Saeli'!F10)=0,0,COUNTA('Jaycie Liu'!F10,'Orson Lee'!F10,'Maria Herrmann'!F10,'Eva Huang'!F10,'Yuki Saeli'!F10)) -> 5 | G10: =IF(COUNTA('Jaycie Liu'!G10,'Orson Lee'!G10,'Maria Herrmann'!G10,'Eva Huang'!G10,'Yuki Saeli'!G10)=0,0,COUNTA('Jaycie Liu'!G10,'Orson Lee'!G10,'Maria Herrmann'!G10,'Eva Huang'!G10,'Yuki Saeli'!G10)) -> 5 | H10: =IF(COUNTA('Jaycie Liu'!H10,'Orson Lee'!H10,'Maria Herrmann'!H10,'Eva Huang'!H10,'Yuki Saeli'!H10)=0,0,COUNTA('Jaycie Liu'!H10,'Orson Lee'!H10,'Maria Herrmann'!H10,'Eva Huang'!H10,'Yuki Saeli'!H10)) -> 5
A11: =TEXT(TIMEVALUE(LEFT(A10,FIND(" -",A10)-1))+TIME(0,30,0), "h:mm AM/PM") & " - " & TEXT(TIMEVALUE(MID(A10,FIND("- ",A10)+2,99))+TIME(0,30,0), "h:mm AM/PM") -> 5:00 AM - 5:30 AM | B11: =IF(COUNTA('Jaycie Liu'!B11,'Orson Lee'!B11,'Maria Herrmann'!B11,'Eva Huang'!B11,'Yuki Saeli'!B11)=0,0,COUNTA('Jaycie Liu'!B11,'Orson Lee'!B11,'Maria Herrmann'!B11,'Eva Huang'!B11,'Yuki Saeli'!B11)) -> 5 | C11: =IF(COUNTA('Jaycie Liu'!C11,'Orson Lee'!C11,'Maria Herrmann'!C11,'Eva Huang'!C11,'Yuki Saeli'!C11)=0,0,COUNTA('Jaycie Liu'!C11,'Orson Lee'!C11,'Maria Herrmann'!C11,'Eva Huang'!C11,'Yuki Saeli'!C11)) -> 5 | D11: =IF(COUNTA('Jaycie Liu'!D11,'Orson Lee'!D11,'Maria Herrmann'!D11,'Eva Huang'!D11,'Yuki Saeli'!D11)=0,0,COUNTA('Jaycie Liu'!D11,'Orson Lee'!D11,'Maria Herrmann'!D11,'Eva Huang'!D11,'Yuki Saeli'!D11)) -> 5 | E11: =IF(COUNTA('Jaycie Liu'!E11,'Orson Lee'!E11,'Maria Herrmann'!E11,'Eva Huang'!E11,'Yuki Saeli'!E11)=0,0,COUNTA('Jaycie Liu'!E11,'Orson Lee'!E11,'Maria Herrmann'!E11,'Eva Huang'!E11,'Yuki Saeli'!E11)) -> 5 | F11: =IF(COUNTA('Jaycie Liu'!F11,'Orson Lee'!F11,'Maria Herrmann'!F11,'Eva Huang'!F11,'Yuki Saeli'!F11)=0,0,COUNTA('Jaycie Liu'!F11,'Orson Lee'!F11,'Maria Herrmann'!F11,'Eva Huang'!F11,'Yuki Saeli'!F11)) -> 5 | G11: =IF(COUNTA('Jaycie Liu'!G11,'Orson Lee'!G11,'Maria Herrmann'!G11,'Eva Huang'!G11,'Yuki Saeli'!G11)=0,0,COUNTA('Jaycie Liu'!G11,'Orson Lee'!G11,'Maria Herrmann'!G11,'Eva Huang'!G11,'Yuki Saeli'!G11)) -> 5 | H11: =IF(COUNTA('Jaycie Liu'!H11,'Orson Lee'!H11,'Maria Herrmann'!H11,'Eva Huang'!H11,'Yuki Saeli'!H11)=0,0,COUNTA('Jaycie Liu'!H11,'Orson Lee'!H11,'Maria Herrmann'!H11,'Eva Huang'!H11,'Yuki Saeli'!H11)) -> 5
A12: =TEXT(TIMEVALUE(LEFT(A11,FIND(" -",A11)-1))+TIME(0,30,0), "h:mm AM/PM") & " - " & TEXT(TIMEVALUE(MID(A11,FIND("- ",A11)+2,99))+TIME(0,30,0), "h:mm AM/PM") -> 5:30 AM - 6:00 AM | B12: =IF(COUNTA('Jaycie Liu'!B12,'Orson Lee'!B12,'Maria Herrmann'!B12,'Eva Huang'!B12,'Yuki Saeli'!B12)=0,0,COUNTA('Jaycie Liu'!B12,'Orson Lee'!B12,'Maria Herrmann'!B12,'Eva Huang'!B12,'Yuki Saeli'!B12)) -> 5 | C12: =IF(COUNTA('Jaycie Liu'!C12,'Orson Lee'!C12,'Maria Herrmann'!C12,'Eva Huang'!C12,'Yuki Saeli'!C12)=0,0,COUNTA('Jaycie Liu'!C12,'Orson Lee'!C12,'Maria Herrmann'!C12,'Eva Huang'!C12,'Yuki Saeli'!C12)) -> 5 | D12: =IF(COUNTA('Jaycie Liu'!D12,'Orson Lee'!D12,'Maria Herrmann'!D12,'Eva Huang'!D12,'Yuki Saeli'!D12)=0,0,COUNTA('Jaycie Liu'!D12,'Orson Lee'!D12,'Maria Herrmann'!D12,'Eva Huang'!D12,'Yuki Saeli'!D12)) -> 5 | E12: =IF(COUNTA('Jaycie Liu'!E12,'Orson Lee'!E12,'Maria Herrmann'!E12,'Eva Huang'!E12,'Yuki Saeli'!E12)=0,0,COUNTA('Jaycie Liu'!E12,'Orson Lee'!E12,'Maria Herrmann'!E12,'Eva Huang'!E12,'Yuki Saeli'!E12)) -> 5 | F12: =IF(COUNTA('Jaycie Liu'!F12,'Orson Lee'!F12,'Maria Herrmann'!F12,'Eva Huang'!F12,'Yuki Saeli'!F12)=0,0,COUNTA('Jaycie Liu'!F12,'Orson Lee'!F12,'Maria Herrmann'!F12,'Eva Huang'!F12,'Yuki Saeli'!F12)) -> 5 | G12: =IF(COUNTA('Jaycie Liu'!G12,'Orson Lee'!G12,'Maria Herrmann'!G12,'Eva Huang'!G12,'Yuki Saeli'!G12)=0,0,COUNTA('Jaycie Liu'!G12,'Orson Lee'!G12,'Maria Herrmann'!G12,'Eva Huang'!G12,'Yuki Saeli'!G12)) -> 5 | H12: =IF(COUNTA('Jaycie Liu'!H12,'Orson Lee'!H12,'Maria Herrmann'!H12,'Eva Huang'!H12,'Yuki Saeli'!H12)=0,0,COUNTA('Jaycie Liu'!H12,'Orson Lee'!H12,'Maria Herrmann'!H12,'Eva Huang'!H12,'Yuki Saeli'!H12)) -> 5
A13: =TEXT(TIMEVALUE(LEFT(A12,FIND(" -",A12)-1))+TIME(0,30,0), "h:mm AM/PM") & " - " & TEXT(TIMEVALUE(MID(A12,FIND("- ",A12)+2,99))+TIME(0,30,0), "h:mm AM/PM") -> 6:00 AM - 6:30 AM | B13: =IF(COUNTA('Jaycie Liu'!B13,'Orson Lee'!B13,'Maria Herrmann'!B13,'Eva Huang'!B13,'Yuki Saeli'!B13)=0,0,COUNTA('Jaycie Liu'!B13,'Orson Lee'!B13,'Maria Herrmann'!B13,'Eva Huang'!B13,'Yuki Saeli'!B13)) -> 5 | C13: =IF(COUNTA('Jaycie Liu'!C13,'Orson Lee'!C13,'Maria Herrmann'!C13,'Eva Huang'!C13,'Yuki Saeli'!C13)=0,0,COUNTA('Jaycie Liu'!C13,'Orson Lee'!C13,'Maria Herrmann'!C13,'Eva Huang'!C13,'Yuki Saeli'!C13)) -> 5 | D13: =IF(COUNTA('Jaycie Liu'!D13,'Orson Lee'!D13,'Maria Herrmann'!D13,'Eva Huang'!D13,'Yuki Saeli'!D13)=0,0,COUNTA('Jaycie Liu'!D13,'Orson Lee'!D13,'Maria Herrmann'!D13,'Eva Huang'!D13,'Yuki Saeli'!D13)) -> 5 | E13: =IF(COUNTA('Jaycie Liu'!E13,'Orson Lee'!E13,'Maria Herrmann'!E13,'Eva Huang'!E13,'Yuki Saeli'!E13)=0,0,COUNTA('Jaycie Liu'!E13,'Orson Lee'!E13,'Maria Herrmann'!E13,'Eva Huang'!E13,'Yuki Saeli'!E13)) -> 5 | F13: =IF(COUNTA('Jaycie Liu'!F13,'Orson Lee'!F13,'Maria Herrmann'!F13,'Eva Huang'!F13,'Yuki Saeli'!F13)=0,0,COUNTA('Jaycie Liu'!F13,'Orson Lee'!F13,'Maria Herrmann'!F13,'Eva Huang'!F13,'Yuki Saeli'!F13)) -> 5 | G13: =IF(COUNTA('Jaycie Liu'!G13,'Orson Lee'!G13,'Maria Herrmann'!G13,'Eva Huang'!G13,'Yuki Saeli'!G13)=0,0,COUNTA('Jaycie Liu'!G13,'Orson Lee'!G13,'Maria Herrmann'!G13,'Eva Huang'!G13,'Yuki Saeli'!G13)) -> 5 | H13: =IF(COUNTA('Jaycie Liu'!H13,'Orson Lee'!H13,'Maria Herrmann'!H13,'Eva Huang'!H13,'Yuki Saeli'!H13)=0,0,COUNTA('Jaycie Liu'!H13,'Orson Lee'!H13,'Maria Herrmann'!H13,'Eva Huang'!H13,'Yuki Saeli'!H13)) -> 5
A14: =TEXT(TIMEVALUE(LEFT(A13,FIND(" -",A13)-1))+TIME(0,30,0), "h:mm AM/PM") & " - " & TEXT(TIMEVALUE(MID(A13,FIND("- ",A13)+2,99))+TIME(0,30,0), "h:mm AM/PM") -> 6:30 AM - 7:00 AM | B14: =IF(COUNTA('Jaycie Liu'!B14,'Orson Lee'!B14,'Maria Herrmann'!B14,'Eva Huang'!B14,'Yuki Saeli'!B14)=0,0,COUNTA('Jaycie Liu'!B14,'Orson Lee'!B14,'Maria Herrmann'!B14,'Eva Huang'!B14,'Yuki Saeli'!B14)) -> 5 | C14: =IF(COUNTA('Jaycie Liu'!C14,'Orson Lee'!C14,'Maria Herrmann'!C14,'Eva Huang'!C14,'Yuki Saeli'!C14)=0,0,COUNTA('Jaycie Liu'!C14,'Orson Lee'!C14,'Maria Herrmann'!C14,'Eva Huang'!C14,'Yuki Saeli'!C14)) -> 4 | D14: =IF(COUNTA('Jaycie Liu'!D14,'Orson Lee'!D14,'Maria Herrmann'!D14,'Eva Huang'!D14,'Yuki Saeli'!D14)=0,0,COUNTA('Jaycie Liu'!D14,'Orson Lee'!D14,'Maria Herrmann'!D14,'Eva Huang'!D14,'Yuki Saeli'!D14)) -> 4 | E14: =IF(COUNTA('Jaycie Liu'!E14,'Orson Lee'!E14,'Maria Herrmann'!E14,'Eva Huang'!E14,'Yuki Saeli'!E14)=0,0,COUNTA('Jaycie Liu'!E14,'Orson Lee'!E14,'Maria Herrmann'!E14,'Eva Huang'!E14,'Yuki Saeli'!E14)) -> 4 | F14: =IF(COUNTA('Jaycie Liu'!F14,'Orson Lee'!F14,'Maria Herrmann'!F14,'Eva Huang'!F14,'Yuki Saeli'!F14)=0,0,COUNTA('Jaycie Liu'!F14,'Orson Lee'!F14,'Maria Herrmann'!F14,'Eva Huang'!F14,'Yuki Saeli'!F14)) -> 5 | G14: =IF(COUNTA('Jaycie Liu'!G14,'Orson Lee'!G14,'Maria Herrmann'!G14,'Eva Huang'!G14,'Yuki Saeli'!G14)=0,0,COUNTA('Jaycie Liu'!G14,'Orson Lee'!G14,'Maria Herrmann'!G14,'Eva Huang'!G14,'Yuki Saeli'!G14)) -> 5 | H14: =IF(COUNTA('Jaycie Liu'!H14,'Orson Lee'!H14,'Maria Herrmann'!H14,'Eva Huang'!H14,'Yuki Saeli'!H14)=0,0,COUNTA('Jaycie Liu'!H14,'Orson Lee'!H14,'Maria Herrmann'!H14,'Eva Huang'!H14,'Yuki Saeli'!H14)) -> 5
A15: =TEXT(TIMEVALUE(LEFT(A14,FIND(" -",A14)-1))+TIME(0,30,0), "h:mm AM/PM") & " - " & TEXT(TIMEVALUE(MID(A14,FIND("- ",A14)+2,99))+TIME(0,30,0), "h:mm AM/PM") -> 7:00 AM - 7:30 AM | B15: =IF(COUNTA('Jaycie Liu'!B15,'Orson Lee'!B15,'Maria Herrmann'!B15,'Eva Huang'!B15,'Yuki Saeli'!B15)=0,0,COUNTA('Jaycie Liu'!B15,'Orson Lee'!B15,'Maria Herrmann'!B15,'Eva Huang'!B15,'Yuki Saeli'!B15)) -> 5 | C15: =IF(COUNTA('Jaycie Liu'!C15,'Orson Lee'!C15,'Maria Herrmann'!C15,'Eva Huang'!C15,'Yuki Saeli'!C15)=0,0,COUNTA('Jaycie Liu'!C15,'Orson Lee'!C15,'Maria Herrmann'!C15,'Eva Huang'!C15,'Yuki Saeli'!C15)) -> 4 | D15: =IF(COUNTA('Jaycie Liu'!D15,'Orson Lee'!D15,'Maria Herrmann'!D15,'Eva Huang'!D15,'Yuki Saeli'!D15)=0,0,COUNTA('Jaycie Liu'!D15,'Orson Lee'!D15,'Maria Herrmann'!D15,'Eva Huang'!D15,'Yuki Saeli'!D15)) -> 4 | E15: =IF(COUNTA('Jaycie Liu'!E15,'Orson Lee'!E15,'Maria Herrmann'!E15,'Eva Huang'!E15,'Yuki Saeli'!E15)=0,0,COUNTA('Jaycie Liu'!E15,'Orson Lee'!E15,'Maria Herrmann'!E15,'Eva Huang'!E15,'Yuki Saeli'!E15)) -> 4 | F15: =IF(COUNTA('Jaycie Liu'!F15,'Orson Lee'!F15,'Maria Herrmann'!F15,'Eva Huang'!F15,'Yuki Saeli'!F15)=0,0,COUNTA('Jaycie Liu'!F15,'Orson Lee'!F15,'Maria Herrmann'!F15,'Eva Huang'!F15,'Yuki Saeli'!F15)) -> 5 | G15: =IF(COUNTA('Jaycie Liu'!G15,'Orson Lee'!G15,'Maria Herrmann'!G15,'Eva Huang'!G15,'Yuki Saeli'!G15)=0,0,COUNTA('Jaycie Liu'!G15,'Orson Lee'!G15,'Maria Herrmann'!G15,'Eva Huang'!G15,'Yuki Saeli'!G15)) -> 5 | H15: =IF(COUNTA('Jaycie Liu'!H15,'Orson Lee'!H15,'Maria Herrmann'!H15,'Eva Huang'!H15,'Yuki Saeli'!H15)=0,0,COUNTA('Jaycie Liu'!H15,'Orson Lee'!H15,'Maria Herrmann'!H15,'Eva Huang'!H15,'Yuki Saeli'!H15)) -> 5
A16: =TEXT(TIMEVALUE(LEFT(A15,FIND(" -",A15)-1))+TIME(0,30,0), "h:mm AM/PM") & " - " & TEXT(TIMEVALUE(MID(A15,FIND("- ",A15)+2,99))+TIME(0,30,0), "h:mm AM/PM") -> 7:30 AM - 8:00 AM | B16: =IF(COUNTA('Jaycie Liu'!B16,'Orson Lee'!B16,'Maria Herrmann'!B16,'Eva Huang'!B16,'Yuki Saeli'!B16)=0,0,COUNTA('Jaycie Liu'!B16,'Orson Lee'!B16,'Maria Herrmann'!B16,'Eva Huang'!B16,'Yuki Saeli'!B16)) -> 5 | C16: =IF(COUNTA('Jaycie Liu'!C16,'Orson Lee'!C16,'Maria Herrmann'!C16,'Eva Huang'!C16,'Yuki Saeli'!C16)=0,0,COUNTA('Jaycie Liu'!C16,'Orson Lee'!C16,'Maria Herrmann'!C16,'Eva Huang'!C16,'Yuki Saeli'!C16)) -> 5 | D16: =IF(COUNTA('Jaycie Liu'!D16,'Orson Lee'!D16,'Maria Herrmann'!D16,'Eva Huang'!D16,'Yuki Saeli'!D16)=0,0,COUNTA('Jaycie Liu'!D16,'Orson Lee'!D16,'Maria Herrmann'!D16,'Eva Huang'!D16,'Yuki Saeli'!D16)) -> 4 | E16: =IF(COUNTA('Jaycie Liu'!E16,'Orson Lee'!E16,'Maria Herrmann'!E16,'Eva Huang'!E16,'Yuki Saeli'!E16)=0,0,COUNTA('Jaycie Liu'!E16,'Orson Lee'!E16,'Maria Herrmann'!E16,'Eva Huang'!E16,'Yuki Saeli'!E16)) -> 5 | F16: =IF(COUNTA('Jaycie Liu'!F16,'Orson Lee'!F16,'Maria Herrmann'!F16,'Eva Huang'!F16,'Yuki Saeli'!F16)=0,0,COUNTA('Jaycie Liu'!F16,'Orson Lee'!F16,'Maria Herrmann'!F16,'Eva Huang'!F16,'Yuki Saeli'!F16)) -> 5 | G16: =IF(COUNTA('Jaycie Liu'!G16,'Orson Lee'!G16,'Maria Herrmann'!G16,'Eva Huang'!G16,'Yuki Saeli'!G16)=0,0,COUNTA('Jaycie Liu'!G16,'Orson Lee'!G16,'Maria Herrmann'!G16,'Eva Huang'!G16,'Yuki Saeli'!G16)) -> 5 | H16: =IF(COUNTA('Jaycie Liu'!H16,'Orson Lee'!H16,'Maria Herrmann'!H16,'Eva Huang'!H16,'Yuki Saeli'!H16)=0,0,COUNTA('Jaycie Liu'!H16,'Orson Lee'!H16,'Maria Herrmann'!H16,'Eva Huang'!H16,'Yuki Saeli'!H16)) -> 5
A17: =TEXT(TIMEVALUE(LEFT(A16,FIND(" -",A16)-1))+TIME(0,30,0), "h:mm AM/PM") & " - " & TEXT(TIMEVALUE(MID(A16,FIND("- ",A16)+2,99))+TIME(0,30,0), "h:mm AM/PM") -> 8:00 AM - 8:30 AM | B17: =IF(COUNTA('Jaycie Liu'!B17,'Orson Lee'!B17,'Maria Herrmann'!B17,'Eva Huang'!B17,'Yuki Saeli'!B17)=0,0,COUNTA('Jaycie Liu'!B17,'Orson Lee'!B17,'Maria Herrmann'!B17,'Eva Huang'!B17,'Yuki Saeli'!B17)) -> 3 | C17: =IF(COUNTA('Jaycie Liu'!C17,'Orson Lee'!C17,'Maria Herrmann'!C17,'Eva Huang'!C17,'Yuki Saeli'!C17)=0,0,COUNTA('Jaycie Liu'!C17,'Orson Lee'!C17,'Maria Herrmann'!C17,'Eva Huang'!C17,'Yuki Saeli'!C17)) -> 3 | D17: =IF(COUNTA('Jaycie Liu'!D17,'Orson Lee'!D17,'Maria Herrmann'!D17,'Eva Huang'!D17,'Yuki Saeli'!D17)=0,0,COUNTA('Jaycie Liu'!D17,'Orson Lee'!D17,'Maria Herrmann'!D17,'Eva Huang'!D17,'Yuki Saeli'!D17)) -> 2 | E17: =IF(COUNTA('Jaycie Liu'!E17,'Orson Lee'!E17,'Maria Herrmann'!E17,'Eva Huang'!E17,'Yuki Saeli'!E17)=0,0,COUNTA('Jaycie Liu'!E17,'Orson Lee'!E17,'Maria Herrmann'!E17,'Eva Huang'!E17,'Yuki Saeli'!E17)) -> 3 | F17: =IF(COUNTA('Jaycie Liu'!F17,'Orson Lee'!F17,'Maria Herrmann'!F17,'Eva Huang'!F17,'Yuki Saeli'!F17)=0,0,COUNTA('Jaycie Liu'!F17,'Orson Lee'!F17,'Maria Herrmann'!F17,'Eva Huang'!F17,'Yuki Saeli'!F17)) -> 2 | G17: =IF(COUNTA('Jaycie Liu'!G17,'Orson Lee'!G17,'Maria Herrmann'!G17,'Eva Huang'!G17,'Yuki Saeli'!G17)=0,0,COUNTA('Jaycie Liu'!G17,'Orson Lee'!G17,'Maria Herrmann'!G17,'Eva Huang'!G17,'Yuki Saeli'!G17)) -> 2 | H17: =IF(COUNTA('Jaycie Liu'!H17,'Orson Lee'!H17,'Maria Herrmann'!H17,'Eva Huang'!H17,'Yuki Saeli'!H17)=0,0,COUNTA('Jaycie Liu'!H17,'Orson Lee'!H17,'Maria Herrmann'!H17,'Eva Huang'!H17,'Yuki Saeli'!H17)) -> 2
